Workbook

Sheet README
A1: Circular Subscription Unit-Economics Simulation Model (Weekly Apparel)
A3: Purpose: model weekly apparel subscription economics where revenue is time-based (user-week) and costs accrue per reuse cycle with explicit logistics, cleaning, labor, loss/damage, and retirement.
A5: How to use:
A6: 1) Inputs: adjust blue manual assumptions OR set Scenario_Mode=1 and choose Scenario_Select (1=Best, 2=Base, 3=Failure).
A7: 2) Scale: set Active_Users and review contribution, break-even, inventory required, capital, and replacement flow.
A8: 3) UnitEconomics: review per-cycle revenue, cost stack, and contribution margin (with/without capital charge).
A9: 4) MonteCarlo: review distribution of per-cycle CM under variance and discrete friction events.
A10: 5) KillConditions: check structural viability flags.
A11: 6) Trajectory: simulate week-by-week dynamics (growth, churn, capacity steps, inventory ordering, and cash runway).
A12: Notes:
A13: - This workbook models friction explicitly (mis-ships, late returns, loss, damage, repairs) and includes safety stock inflation from cycle-time variance.
A14: - Scale effects are optional and controlled by ENABLE_SCALE_EFFECTS.
A15: - RAND()-based Monte Carlo will change on recalculation; copy/paste values if you want to freeze a run.

Sheet Inputs
A1: Inputs (blue = editable manual). Effective values feed the model.
A3: Scenario_Mode (0=Manual, 1=Use Scenario Library) | B3: 1
A4: Scenario_Select (1=Best, 2=Base, 3=Failure) | B4: 2
A6: Parameter | B6: Manual | C6: Effective | D6: Units | E6: Notes
A7: PRICE_WEEKLY_USD | B7: 39 | C7: =IF($B$3=0,B7,VLOOKUP(A7,Scenarios!$A$4:$D$200,1+$B$4,FALSE)) | D7: USD | E7: Subscription price per active user-week
A8: DISCOUNT_RATE | B8: 0.08 | C8: =IF($B$3=0,B8,VLOOKUP(A8,Scenarios!$A$4:$D$200,1+$B$4,FALSE)) | D8: % | E8: Average discount rate (0-1)
A9: BASE_RETURN_LATENCY_WEEKS | B9: 1.05 | C9: =IF($B$3=0,B9,VLOOKUP(A9,Scenarios!$A$4:$D$200,1+$B$4,FALSE)) | D9: weeks | E9: Outbound-to-inbound latency excluding cleaning
A10: LATE_RETURN_PROB | B10: 0.18 | C10: =IF($B$3=0,B10,VLOOKUP(A10,Scenarios!$A$4:$D$200,1+$B$4,FALSE)) | D10: % | E10: Probability return exceeds target window
A11: LATE_RETURN_EXTRA_WEEKS | B11: 0.55 | C11: =IF($B$3=0,B11,VLOOKUP(A11,Scenarios!$A$4:$D$200,1+$B$4,FALSE)) | D11: weeks | E11: Additional weeks conditional on late return
A12: CLEAN_TAT_WEEKS | B12: 0.35 | C12: =IF($B$3=0,B12,VLOOKUP(A12,Scenarios!$A$4:$D$200,1+$B$4,FALSE)) | D12: weeks | E12: Cleaning + QA turnaround time
A13: SIGMA_RETURN_WEEKS | B13: 0.3 | C13: =IF($B$3=0,B13,VLOOKUP(A13,Scenarios!$A$4:$D$200,1+$B$4,FALSE)) | D13: weeks | E13: Std dev of return latency
A14: SIGMA_CLEAN_WEEKS | B14: 0.1 | C14: =IF($B$3=0,B14,VLOOKUP(A14,Scenarios!$A$4:$D$200,1+$B$4,FALSE)) | D14: weeks | E14: Std dev of cleaning TAT
A15: SERVICE_LEVEL | B15: 0.95 | C15: =IF($B$3=0,B15,VLOOKUP(A15,Scenarios!$A$4:$D$200,1+$B$4,FALSE)) | D15: % | E15: Service level target for safety stock factor
A16: ITEMS_PER_BOX | B16: 4 | C16: =IF($B$3=0,B16,VLOOKUP(A16,Scenarios!$A$4:$D$200,1+$B$4,FALSE)) | E16: Average garments per shipment
A17: GARMENT_ACQ_COST_USD | B17: 25 | C17: =IF($B$3=0,B17,VLOOKUP(A17,Scenarios!$A$4:$D$200,1+$B$4,FALSE)) | D17: USD | E17: Weighted avg acquisition cost per garment
A18: GARMENT_LIFE_CYCLES_WEAR | B18: 28 | C18: =IF($B$3=0,B18,VLOOKUP(A18,Scenarios!$A$4:$D$200,1+$B$4,FALSE)) | D18: cycles | E18: Wear-out cycles excluding loss/damage
A19: LOSS_PROB | B19: 0.009 | C19: =IF($B$3=0,B19,VLOOKUP(A19,Scenarios!$A$4:$D$200,1+$B$4,FALSE)) | D19: % | E19: Permanent loss probability per garment-cycle
A20: DAMAGE_PROB | B20: 0.055 | C20: =IF($B$3=0,B20,VLOOKUP(A20,Scenarios!$A$4:$D$200,1+$B$4,FALSE)) | D20: % | E20: Damage probability per garment-cycle
A21: DAMAGE_RETIRE_PROB | B21: 0.35 | C21: =IF($B$3=0,B21,VLOOKUP(A21,Scenarios!$A$4:$D$200,1+$B$4,FALSE)) | D21: % | E21: Share of damaged garments retired
A22: REPAIR_COST_USD | B22: 6.5 | C22: =IF($B$3=0,B22,VLOOKUP(A22,Scenarios!$A$4:$D$200,1+$B$4,FALSE)) | D22: USD | E22: Repair cost conditional on repairable damage
A23: CLEAN_COST_USD | B23: 2.6 | C23: =IF($B$3=0,B23,VLOOKUP(A23,Scenarios!$A$4:$D$200,1+$B$4,FALSE)) | D23: USD | E23: Cleaning/finishing cost per garment-cycle
A24: QA_COST_USD | B24: 0.75 | C24: =IF($B$3=0,B24,VLOOKUP(A24,Scenarios!$A$4:$D$200,1+$B$4,FALSE)) | D24: USD | E24: QA/rebag cost per garment-cycle
A25: OUTBOUND_SHIP_USD | B25: 8.2 | C25: =IF($B$3=0,B25,VLOOKUP(A25,Scenarios!$A$4:$D$200,1+$B$4,FALSE)) | D25: USD | E25: Outbound shipping cost per box
A26: INBOUND_SHIP_USD | B26: 6.8 | C26: =IF($B$3=0,B26,VLOOKUP(A26,Scenarios!$A$4:$D$200,1+$B$4,FALSE)) | D26: USD | E26: Inbound shipping cost per box
A27: PACKAGING_DEP_USD | B27: 1.1 | C27: =IF($B$3=0,B27,VLOOKUP(A27,Scenarios!$A$4:$D$200,1+$B$4,FALSE)) | D27: USD | E27: Packaging depreciation per cycle
A28: PICKPACK_LABOR_USD | B28: 3.1 | C28: =IF($B$3=0,B28,VLOOKUP(A28,Scenarios!$A$4:$D$200,1+$B$4,FALSE)) | D28: USD | E28: Pick/pack labor per box-cycle
... A57: FAILURE_PROB_KILL | B57: 0.2 | C57: =IF($B$3=0,B57,VLOOKUP(A57,Scenarios!$A$4:$D$200,1+$B$4,FALSE)) | D57: % | E57: Kill threshold: Monte Carlo Pr(CM<0)
A60: Trajectory & Cash Simulation (week-by-week system dynamics)
A62: HORIZON_WEEKS | B62: 104 | C62: =IF($B$3=0,B62,VLOOKUP(A62,Scenarios!$A$4:$D$400,1+$B$4,FALSE))
A63: START_ACTIVE_USERS | B63: 250 | C63: =IF($B$3=0,B63,VLOOKUP(A63,Scenarios!$A$4:$D$400,1+$B$4,FALSE))
A64: WEEKLY_NEW_USERS | B64: 20 | C64: =IF($B$3=0,B64,VLOOKUP(A64,Scenarios!$A$4:$D$400,1+$B$4,FALSE))
A65: CAC_USD | B65: 25 | C65: =IF($B$3=0,B65,VLOOKUP(A65,Scenarios!$A$4:$D$400,1+$B$4,FALSE))
A66: BASE_CHURN_WEEKLY | B66: 0.015 | C66: =IF($B$3=0,B66,VLOOKUP(A66,Scenarios!$A$4:$D$400,1+$B$4,FALSE))
A67: CHURN_SENS_REFUND | B67: 1.2 | C67: =IF($B$3=0,B67,VLOOKUP(A67,Scenarios!$A$4:$D$400,1+$B$4,FALSE))
A68: CHURN_SENS_STOCKOUT | B68: 0.5 | C68: =IF($B$3=0,B68,VLOOKUP(A68,Scenarios!$A$4:$D$400,1+$B$4,FALSE))
A69: CHURN_SENS_LATE | B69: 0.2 | C69: =IF($B$3=0,B69,VLOOKUP(A69,Scenarios!$A$4:$D$400,1+$B$4,FALSE))
A70: STOCKOUT_REFUND_ADD | B70: 0.8 | C70: =IF($B$3=0,B70,VLOOKUP(A70,Scenarios!$A$4:$D$400,1+$B$4,FALSE))
A71: STOCKOUT_PENALTY_USD | B71: 6 | C71: =IF($B$3=0,B71,VLOOKUP(A71,Scenarios!$A$4:$D$400,1+$B$4,FALSE))
A72: START_CASH_USD | B72: 150000 | C72: =IF($B$3=0,B72,VLOOKUP(A72,Scenarios!$A$4:$D$400,1+$B$4,FALSE))
A73: INVENTORY_LEAD_WEEKS | B73: 1 | C73: =IF($B$3=0,B73,VLOOKUP(A73,Scenarios!$A$4:$D$400,1+$B$4,FALSE))
...

Sheet Lookups
A1: Service_Level | B1: Z_Score
A2: 0.8 | B2: 0.8416
A3: 0.85 | B3: 1.0364
A4: 0.9 | B4: 1.2816
A5: 0.92 | B5: 1.4051
A6: 0.94 | B6: 1.5548
A7: 0.95 | B7: 1.6449
A8: 0.96 | B8: 1.7507
A9: 0.97 | B9: 1.8808
A10: 0.975 | B10: 1.96
A11: 0.98 | B11: 2.0537
A12: 0.985 | B12: 2.1701
A13: 0.99 | B13: 2.3263
A14: 0.995 | B14: 2.5758

Sheet Scenarios
A1: Scenario Library (used when Scenario_Mode = 1)
A3: Parameter | B3: Best | C3: Base | D3: Failure | E3: Notes
A4: PRICE_WEEKLY_USD | B4: 49 | C4: 39 | D4: 29 | E4: Subscription price per active user-week
A5: DISCOUNT_RATE | B5: 0.02 | C5: 0.08 | D5: 0.15 | E5: Average discount rate (0-1)
A6: BASE_RETURN_LATENCY_WEEKS | B6: 0.85 | C6: 1.05 | D6: 1.35 | E6: Outbound-to-inbound latency excluding cleaning
A7: LATE_RETURN_PROB | B7: 0.08 | C7: 0.18 | D7: 0.35 | E7: Probability return exceeds target window
A8: LATE_RETURN_EXTRA_WEEKS | B8: 0.3 | C8: 0.55 | D8: 0.9 | E8: Additional weeks conditional on late return
A9: CLEAN_TAT_WEEKS | B9: 0.25 | C9: 0.35 | D9: 0.55 | E9: Cleaning + QA turnaround time
A10: SIGMA_RETURN_WEEKS | B10: 0.18 | C10: 0.3 | D10: 0.45 | E10: Std dev of return latency
A11: SIGMA_CLEAN_WEEKS | B11: 0.06 | C11: 0.1 | D11: 0.18 | E11: Std dev of cleaning TAT
A12: SERVICE_LEVEL | B12: 0.97 | C12: 0.95 | D12: 0.9 | E12: Service level target for safety stock factor
A13: ITEMS_PER_BOX | B13: 4 | C13: 4 | D13: 4 | E13: Average garments per shipment
A14: GARMENT_ACQ_COST_USD | B14: 22 | C14: 25 | D14: 28 | E14: Weighted avg acquisition cost per garment
A15: GARMENT_LIFE_CYCLES_WEAR | B15: 35 | C15: 28 | D15: 18 | E15: Wear-out cycles excluding loss/damage
... A39: USERS_PER_SITE | B39: 4000 | C39: 3000 | D39: 2200 | E39: User capacity per site per week (step function)
A40: HORIZON_WEEKS | B40: 104 | C40: 104 | D40: 104
A41: START_ACTIVE_USERS | B41: 500 | C41: 250 | D41: 250
A42: WEEKLY_NEW_USERS | B42: 60 | C42: 20 | D42: 10
A43: CAC_USD | B43: 15 | C43: 25 | D43: 35
A44: BASE_CHURN_WEEKLY | B44: 0.008 | C44: 0.015 | D44: 0.035
A45: CHURN_SENS_REFUND | B45: 0.8 | C45: 1.2 | D45: 1.8
A46: CHURN_SENS_STOCKOUT | B46: 0.2 | C46: 0.5 | D46: 1.2
A47: CHURN_SENS_LATE | B47: 0.1 | C47: 0.2 | D47: 0.4
A48: STOCKOUT_REFUND_ADD | B48: 0.5 | C48: 0.8 | D48: 1.2
A49: STOCKOUT_PENALTY_USD | B49: 3 | C49: 6 | D49: 10
A50: START_CASH_USD | B50: 250000 | C50: 150000 | D50: 80000
A51: INVENTORY_LEAD_WEEKS | B51: 0 | C51: 1 | D51: 2
... A70: RAMP_VAR_COST_MULT_MAX | B70: 1.2 | C70: 1.35 | D70: 1.6

Sheet UnitEconomics
A1: Per User-Week Cycle Unit Economics (time-based revenue; per-cycle marginal costs)
A3: Active Users (for scale effects) | B3: =Scale!$B$3 | D3: Key KPIs
D4: CM per cycle | E4: =B33
A5: Scaled Cost Drivers (optional) | D5: Economic CM per cycle | E5: =B35
A6: Clean_Cost_Eff (per garment) | B6: =Inputs!$C$23*IF(Inputs!$C$43=1,POWER(MAX(1,Scale!$B$3)/Inputs!$C$44,Inputs!$C$45),1) | D6: Var cost per cycle | E6: =B32
A7: PickPack_Labor_Eff (per box) | B7: =Inputs!$C$28*IF(Inputs!$C$43=1,POWER(MAX(1,Scale!$B$3)/Inputs!$C$44,Inputs!$C$46),1) | D7: Net revenue per cycle | E7: =B18
A8: Inbound_Labor_Eff (per box) | B8: =Inputs!$C$29*IF(Inputs!$C$43=1,POWER(MAX(1,Scale!$B$3)/Inputs!$C$44,Inputs!$C$46),1) | D8: Var cost as % revenue | E8: =IF(B18=0,0,B32/B18)
A9: Support_Eff (per user-week) | B9: =Inputs!$C$30*IF(Inputs!$C$43=1,POWER(MAX(1,Scale!$B$3)/Inputs!$C$44,Inputs!$C$47),1)
A10: Outbound_Ship_Eff (per box) | B10: =Inputs!$C$25*(1-IF(Inputs!$C$43=1,Inputs!$C$48*(1-EXP(-MAX(1,Scale!$B$3)/Inputs!$C$49)),0))
A11: Inbound_Ship_Eff (per box) | B11: =Inputs!$C$26*(1-IF(Inputs!$C$43=1,Inputs!$C$48*(1-EXP(-MAX(1,Scale!$B$3)/Inputs!$C$49)),0))
A12: MisShip_Prob_Eff | B12: =MAX(Inputs!$C$50, Inputs!$C$33*IF(Inputs!$C$43=1,EXP(-MAX(1,Scale!$B$3)/Inputs!$C$51),1))
A15: Metric | B15: Per Cycle (USD) | C15: Driver | D15: Notes
A16: Collected revenue (pre-refund) | B16: =Inputs!$C$7*(1-Inputs!$C$8) | C16: Price, discount | D16: Subscription yield per active user-week
A17: Refunds / credits | B17: =-Inputs!$C$7*(1-Inputs!$C$8)*(Inputs!$C$36 + B12*Inputs!$C$37 + Inputs!$C$10*Inputs!$C$38) | C17: Refund model | D17: Expected credits from miship & late returns
A18: Revenue net of refunds | B18: =SUM(B16:B17)
A19: Cleaning + QA | B19: =Inputs!$C$16*(B6+Inputs!$C$24) | C19: Service | D19: Per-garment cycle service cost
A20: Outbound shipping | B20: =B10 | C20: Carrier | D20: Per-box outbound transport
A21: Inbound shipping | B21: =B11 | C21: Carrier | D21: Per-box returns transport
A22: Packaging depreciation | B22: =Inputs!$C$27 | C22: Packaging | D22: Reusable box amortized per cycle
A23: Fulfillment labor (pick/pack) | B23: =B7 | C23: Labor | D23: Variable labor per box-cycle
A24: Inbound processing labor | B24: =B8 | C24: Labor | D24: Receiving, sort, rebag staging
A25: Customer support | B25: =B9 | C25: Support | D25: Variable contacts per user-week
A26: Mis-ship expected incremental | B26: =B12*Inputs!$C$34 | C26: Mis-ship | D26: Reship, credits, extra handling
A27: Late return exception handling | B27: =Inputs!$C$10*Inputs!$C$35 | C27: Late return | D27: Manual exceptions, comms
A28: Wear-out retirement replacement | B28: =Inputs!$C$16*(1/Inputs!$C$18)*Inputs!$C$17 | C28: Wear | D28: Wear-based retirement; excludes loss/damage
A29: Loss replacement | B29: =Inputs!$C$16*Inputs!$C$19*Inputs!$C$17 | C29: Loss | D29: Permanent loss per garment-cycle
A30: Damage replacement + repair | B30: =Inputs!$C$16*Inputs!$C$20*(Inputs!$C$22 + Inputs!$C$21*Inputs!$C$17) | C30: Damage | D30: Repair cost plus retire share
A31: Payment processing fees | B31: =Inputs!$C$31*B18 + Inputs!$C$32 | C31: Payments | D31: Applied on net collected revenue
A32: Total variable cost | B32: =SUM(B19:B31)
A33: Contribution margin (CM) | B33: =B18 - B32
A34: Capital charge per cycle (inventory) | B34: =Scale!$B$15 | C34: Capital | D34: Weekly cost of capital allocated per user-week
A35: Economic CM (after capital) | B35: =B33 - B34

Sheet Scale
A1: Scale & Break-even (100 → 100,000 users) with inventory physics and capacity steps
A3: Active_Users | B3: 1000 | F3: Users | G3: Weekly CM Profit | H3: Weekly Economic Profit | I3: CM / Cycle | J3: Fixed OPEX | K3: CapCharge / Cycle
F4: 100 | G4: =F4*I4 - J4 | H4: =F4*(I4-K4) - J4 | I4: =((Inputs!$C$7*(1-Inputs!$C$8) - Inputs!$C$7*(1-Inputs!$C$8)*(Inputs!$C$36 + MAX(Inputs!$C$50, Inputs!$C$33*IF(Inputs!$C$43=1,EXP(-MAX(1,F4)/Inputs!$C$51),1))*Inputs!$C$37 + Inputs!$C$10*Inputs!$C$38))) - (Inputs!$C$16*((Inputs!$C$23*IF(Inputs!$C$43=1,POWER(MAX(1,F4)/Inputs!$C$44,Inputs!$C$45),1))+Inputs!$C$24) + (Inputs!$C$25*(1-IF(Inputs!$C$43=1,Inputs!$C$48*(1-EXP(-MAX(1,F4)/Inputs!$C$49)),0))) + (Inputs!$C$26*(1-IF(Inputs!$C$43=1,Inputs!$C$48*(1-EXP(-MAX(1,F4)/Inputs!$C$49)),0))) + Inputs!$C$27 + (Inputs!$C$28*IF(Inputs!$C$43=1,POWER(MAX(1,F4)/Inputs!$C$44,Inputs!$C$46),1)) + (Inputs!$C$29*IF(Inputs!$C$43=1,POWER(MAX(1,F4)/Inputs!$C$44,Inputs!$C$46),1)) + (Inputs!$C$30*IF(Inputs!$C$43=1,POWER(MAX(1,F4)/Inputs!$C$44,Inputs!$C$47),1)) + (MAX(Inputs!$C$50, Inputs!$C$33*IF(Inputs!$C$43=1,EXP(-MAX(1,F4)/Inputs!$C$51),1))*Inputs!$C$34) + (Inputs!$C$10*Inputs!$C$35) + Inputs!$C$16*(1/Inputs!$C$18)*Inputs!$C$17 + Inputs!$C$16*Inputs!$C$19*Inputs!$C$17 + Inputs!$C$16*Inputs!$C$20*(Inputs!$C$22 + Inputs!$C$21*Inputs!$C$17) + Inputs!$C$31*(Inputs!$C$7*(1-Inputs!$C$8) - Inputs!$C$7*(1-Inputs!$C$8)*(Inputs!$C$36 + MAX(Inputs!$C$50, Inputs!$C$33*IF(Inputs!$C$43=1,EXP(-MAX(1,F4)/Inputs!$C$51),1))*Inputs!$C$37 + Inputs!$C$10*Inputs!$C$38)) + Inputs!$C$32) | J4: =Inputs!$C$40 + CEILING(F4/Inputs!$C$42,1)*Inputs!$C$41 | K4: =Scale!$B$15
A5: Cycle-time physics (drives inventory multiple) | F5: 200 | G5: =F5*I5 - J5 | H5: =F5*(I5-K5) - J5 | I5: =((Inputs!$C$7*(1-Inputs!$C$8) - Inputs!$C$7*(1-Inputs!$C$8)*(Inputs!$C$36 + MAX(Inputs!$C$50, Inputs!$C$33*IF(Inputs!$C$43=1,EXP(-MAX(1,F5)/Inputs!$C$51),1))*Inputs!$C$37 + Inputs!$C$10*Inputs!$C$38))) - (Inputs!$C$16*((Inputs!$C$23*IF(Inputs!$C$43=1,POWER(MAX(1,F5)/Inputs!$C$44,Inputs!$C$45),1))+Inputs!$C$24) + (Inputs!$C$25*(1-IF(Inputs!$C$43=1,Inputs!$C$48*(1-EXP(-MAX(1,F5)/Inputs!$C$49)),0))) + (Inputs!$C$26*(1-IF(Inputs!$C$43=1,Inputs!$C$48*(1-EXP(-MAX(1,F5)/Inputs!$C$49)),0))) + Inputs!$C$27 + (Inputs!$C$28*IF(Inputs!$C$43=1,POWER(MAX(1,F5)/Inputs!$C$44,Inputs!$C$46),1)) + (Inputs!$C$29*IF(Inputs!$C$43=1,POWER(MAX(1,F5)/Inputs!$C$44,Inputs!$C$46),1)) + (Inputs!$C$30*IF(Inputs!$C$43=1,POWER(MAX(1,F5)/Inputs!$C$44,Inputs!$C$47),1)) + (MAX(Inputs!$C$50, Inputs!$C$33*IF(Inputs!$C$43=1,EXP(-MAX(1,F5)/Inputs!$C$51),1))*Inputs!$C$34) + (Inputs!$C$10*Inputs!$C$35) + Inputs!$C$16*(1/Inputs!$C$18)*Inputs!$C$17 + Inputs!$C$16*Inputs!$C$19*Inputs!$C$17 + Inputs!$C$16*Inputs!$C$20*(Inputs!$C$22 + Inputs!$C$21*Inputs!$C$17) + Inputs!$C$31*(Inputs!$C$7*(1-Inputs!$C$8) - Inputs!$C$7*(1-Inputs!$C$8)*(Inputs!$C$36 + MAX(Inputs!$C$50, Inputs!$C$33*IF(Inputs!$C$43=1,EXP(-MAX(1,F5)/Inputs!$C$51),1))*Inputs!$C$37 + Inputs!$C$10*Inputs!$C$38)) + Inputs!$C$32) | J5: =Inputs!$C$40 + CEILING(F5/Inputs!$C$42,1)*Inputs!$C$41 | K5: =Scale!$B$15
A6: Mean return latency (weeks) | B6: =Inputs!$C$9 + Inputs!$C$10*Inputs!$C$11 | F6: 400 | G6: =F6*I6 - J6 | H6: =F6*(I6-K6) - J6 | I6: =((Inputs!$C$7*(1-Inputs!$C$8) - Inputs!$C$7*(1-Inputs!$C$8)*(Inputs!$C$36 + MAX(Inputs!$C$50, Inputs!$C$33*IF(Inputs!$C$43=1,EXP(-MAX(1,F6)/Inputs!$C$51),1))*Inputs!$C$37 + Inputs!$C$10*Inputs!$C$38))) - (Inputs!$C$16*((Inputs!$C$23*IF(Inputs!$C$43=1,POWER(MAX(1,F6)/Inputs!$C$44,Inputs!$C$45),1))+Inputs!$C$24) + (Inputs!$C$25*(1-IF(Inputs!$C$43=1,Inputs!$C$48*(1-EXP(-MAX(1,F6)/Inputs!$C$49)),0))) + (Inputs!$C$26*(1-IF(Inputs!$C$43=1,Inputs!$C$48*(1-EXP(-MAX(1,F6)/Inputs!$C$49)),0))) + Inputs!$C$27 + (Inputs!$C$28*IF(Inputs!$C$43=1,POWER(MAX(1,F6)/Inputs!$C$44,Inputs!$C$46),1)) + (Inputs!$C$29*IF(Inputs!$C$43=1,POWER(MAX(1,F6)/Inputs!$C$44,Inputs!$C$46),1)) + (Inputs!$C$30*IF(Inputs!$C$43=1,POWER(MAX(1,F6)/Inputs!$C$44,Inputs!$C$47),1)) + (MAX(Inputs!$C$50, Inputs!$C$33*IF(Inputs!$C$43=1,EXP(-MAX(1,F6)/Inputs!$C$51),1))*Inputs!$C$34) + (Inputs!$C$10*Inputs!$C$35) + Inputs!$C$16*(1/Inputs!$C$18)*Inputs!$C$17 + Inputs!$C$16*Inputs!$C$19*Inputs!$C$17 + Inputs!$C$16*Inputs!$C$20*(Inputs!$C$22 + Inputs!$C$21*Inputs!$C$17) + Inputs!$C$31*(Inputs!$C$7*(1-Inputs!$C$8) - Inputs!$C$7*(1-Inputs!$C$8)*(Inputs!$C$36 + MAX(Inputs!$C$50, Inputs!$C$33*IF(Inputs!$C$43=1,EXP(-MAX(1,F6)/Inputs!$C$51),1))*Inputs!$C$37 + Inputs!$C$10*Inputs!$C$38)) + Inputs!$C$32) | J6: =Inputs!$C$40 + CEILING(F6/Inputs!$C$42,1)*Inputs!$C$41 | K6: =Scale!$B$15
A7: Mean cleaning TAT (weeks) | B7: =Inputs!$C$12 | F7: 700 | G7: =F7*I7 - J7 | H7: =F7*(I7-K7) - J7 | I7: =((Inputs!$C$7*(1-Inputs!$C$8) - Inputs!$C$7*(1-Inputs!$C$8)*(Inputs!$C$36 + MAX(Inputs!$C$50, Inputs!$C$33*IF(Inputs!$C$43=1,EXP(-MAX(1,F7)/Inputs!$C$51),1))*Inputs!$C$37 + Inputs!$C$10*Inputs!$C$38))) - (Inputs!$C$16*((Inputs!$C$23*IF(Inputs!$C$43=1,POWER(MAX(1,F7)/Inputs!$C$44,Inputs!$C$45),1))+Inputs!$C$24) + (Inputs!$C$25*(1-IF(Inputs!$C$43=1,Inputs!$C$48*(1-EXP(-MAX(1,F7)/Inputs!$C$49)),0))) + (Inputs!$C$26*(1-IF(Inputs!$C$43=1,Inputs!$C$48*(1-EXP(-MAX(1,F7)/Inputs!$C$49)),0))) + Inputs!$C$27 + (Inputs!$C$28*IF(Inputs!$C$43=1,POWER(MAX(1,F7)/Inputs!$C$44,Inputs!$C$46),1)) + (Inputs!$C$29*IF(Inputs!$C$43=1,POWER(MAX(1,F7)/Inputs!$C$44,Inputs!$C$46),1)) + (Inputs!$C$30*IF(Inputs!$C$43=1,POWER(MAX(1,F7)/Inputs!$C$44,Inputs!$C$47),1)) + (MAX(Inputs!$C$50, Inputs!$C$33*IF(Inputs!$C$43=1,EXP(-MAX(1,F7)/Inputs!$C$51),1))*Inputs!$C$34) + (Inputs!$C$10*Inputs!$C$35) + Inputs!$C$16*(1/Inputs!$C$18)*Inputs!$C$17 + Inputs!$C$16*Inputs!$C$19*Inputs!$C$17 + Inputs!$C$16*Inputs!$C$20*(Inputs!$C$22 + Inputs!$C$21*Inputs!$C$17) + Inputs!$C$31*(Inputs!$C$7*(1-Inputs!$C$8) - Inputs!$C$7*(1-Inputs!$C$8)*(Inputs!$C$36 + MAX(Inputs!$C$50, Inputs!$C$33*IF(Inputs!$C$43=1,EXP(-MAX(1,F7)/Inputs!$C$51),1))*Inputs!$C$37 + Inputs!$C$10*Inputs!$C$38)) + Inputs!$C$32) | J7: =Inputs!$C$40 + CEILING(F7/Inputs!$C$42,1)*Inputs!$C$41 | K7: =Scale!$B$15
A8: Mean total cycle time (weeks) | B8: =B6+B7 | F8: 1000 | G8: =F8*I8 - J8 | H8: =F8*(I8-K8) - J8 | I8: =((Inputs!$C$7*(1-Inputs!$C$8) - Inputs!$C$7*(1-Inputs!$C$8)*(Inputs!$C$36 + MAX(Inputs!$C$50, Inputs!$C$33*IF(Inputs!$C$43=1,EXP(-MAX(1,F8)/Inputs!$C$51),1))*Inputs!$C$37 + Inputs!$C$10*Inputs!$C$38))) - (Inputs!$C$16*((Inputs!$C$23*IF(Inputs!$C$43=1,POWER(MAX(1,F8)/Inputs!$C$44,Inputs!$C$45),1))+Inputs!$C$24) + (Inputs!$C$25*(1-IF(Inputs!$C$43=1,Inputs!$C$48*(1-EXP(-MAX(1,F8)/Inputs!$C$49)),0))) + (Inputs!$C$26*(1-IF(Inputs!$C$43=1,Inputs!$C$48*(1-EXP(-MAX(1,F8)/Inputs!$C$49)),0))) + Inputs!$C$27 + (Inputs!$C$28*IF(Inputs!$C$43=1,POWER(MAX(1,F8)/Inputs!$C$44,Inputs!$C$46),1)) + (Inputs!$C$29*IF(Inputs!$C$43=1,POWER(MAX(1,F8)/Inputs!$C$44,Inputs!$C$46),1)) + (Inputs!$C$30*IF(Inputs!$C$43=1,POWER(MAX(1,F8)/Inputs!$C$44,Inputs!$C$47),1)) + (MAX(Inputs!$C$50, Inputs!$C$33*IF(Inputs!$C$43=1,EXP(-MAX(1,F8)/Inputs!$C$51),1))*Inputs!$C$34) + (Inputs!$C$10*Inputs!$C$35) + Inputs!$C$16*(1/Inputs!$C$18)*Inputs!$C$17 + Inputs!$C$16*Inputs!$C$19*Inputs!$C$17 + Inputs!$C$16*Inputs!$C$20*(Inputs!$C$22 + Inputs!$C$21*Inputs!$C$17) + Inputs!$C$31*(Inputs!$C$7*(1-Inputs!$C$8) - Inputs!$C$7*(1-Inputs!$C$8)*(Inputs!$C$36 + MAX(Inputs!$C$50, Inputs!$C$33*IF(Inputs!$C$43=1,EXP(-MAX(1,F8)/Inputs!$C$51),1))*Inputs!$C$37 + Inputs!$C$10*Inputs!$C$38)) + Inputs!$C$32) | J8: =Inputs!$C$40 + CEILING(F8/Inputs!$C$42,1)*Inputs!$C$41 | K8: =Scale!$B$15
A9: Std dev total cycle time (weeks) | B9: =SQRT(Inputs!$C$13^2 + Inputs!$C$14^2) | F9: 1500 | G9: =F9*I9 - J9 | H9: =F9*(I9-K9) - J9 | I9: =((Inputs!$C$7*(1-Inputs!$C$8) - Inputs!$C$7*(1-Inputs!$C$8)*(Inputs!$C$36 + MAX(Inputs!$C$50, Inputs!$C$33*IF(Inputs!$C$43=1,EXP(-MAX(1,F9)/Inputs!$C$51),1))*Inputs!$C$37 + Inputs!$C$10*Inputs!$C$38))) - (Inputs!$C$16*((Inputs!$C$23*IF(Inputs!$C$43=1,POWER(MAX(1,F9)/Inputs!$C$44,Inputs!$C$45),1))+Inputs!$C$24) + (Inputs!$C$25*(1-IF(Inputs!$C$43=1,Inputs!$C$48*(1-EXP(-MAX(1,F9)/Inputs!$C$49)),0))) + (Inputs!$C$26*(1-IF(Inputs!$C$43=1,Inputs!$C$48*(1-EXP(-MAX(1,F9)/Inputs!$C$49)),0))) + Inputs!$C$27 + (Inputs!$C$28*IF(Inputs!$C$43=1,POWER(MAX(1,F9)/Inputs!$C$44,Inputs!$C$46),1)) + (Inputs!$C$29*IF(Inputs!$C$43=1,POWER(MAX(1,F9)/Inputs!$C$44,Inputs!$C$46),1)) + (Inputs!$C$30*IF(Inputs!$C$43=1,POWER(MAX(1,F9)/Inputs!$C$44,Inputs!$C$47),1)) + (MAX(Inputs!$C$50, Inputs!$C$33*IF(Inputs!$C$43=1,EXP(-MAX(1,F9)/Inputs!$C$51),1))*Inputs!$C$34) + (Inputs!$C$10*Inputs!$C$35) + Inputs!$C$16*(1/Inputs!$C$18)*Inputs!$C$17 + Inputs!$C$16*Inputs!$C$19*Inputs!$C$17 + Inputs!$C$16*Inputs!$C$20*(Inputs!$C$22 + Inputs!$C$21*Inputs!$C$17) + Inputs!$C$31*(Inputs!$C$7*(1-Inputs!$C$8) - Inputs!$C$7*(1-Inputs!$C$8)*(Inputs!$C$36 + MAX(Inputs!$C$50, Inputs!$C$33*IF(Inputs!$C$43=1,EXP(-MAX(1,F9)/Inputs!$C$51),1))*Inputs!$C$37 + Inputs!$C$10*Inputs!$C$38)) + Inputs!$C$32) | J9: =Inputs!$C$40 + CEILING(F9/Inputs!$C$42,1)*Inputs!$C$41 | K9: =Scale!$B$15
A10: Z (service level) | B10: =VLOOKUP(Inputs!$C$15,Lookups!$A$2:$B$20,2,TRUE) | F10: 2200 | G10: =F10*I10 - J10 | H10: =F10*(I10-K10) - J10 | I10: =((Inputs!$C$7*(1-Inputs!$C$8) - Inputs!$C$7*(1-Inputs!$C$8)*(Inputs!$C$36 + MAX(Inputs!$C$50, Inputs!$C$33*IF(Inputs!$C$43=1,EXP(-MAX(1,F10)/Inputs!$C$51),1))*Inputs!$C$37 + Inputs!$C$10*Inputs!$C$38))) - (Inputs!$C$16*((Inputs!$C$23*IF(Inputs!$C$43=1,POWER(MAX(1,F10)/Inputs!$C$44,Inputs!$C$45),1))+Inputs!$C$24) + (Inputs!$C$25*(1-IF(Inputs!$C$43=1,Inputs!$C$48*(1-EXP(-MAX(1,F10)/Inputs!$C$49)),0))) + (Inputs!$C$26*(1-IF(Inputs!$C$43=1,Inputs!$C$48*(1-EXP(-MAX(1,F10)/Inputs!$C$49)),0))) + Inputs!$C$27 + (Inputs!$C$28*IF(Inputs!$C$43=1,POWER(MAX(1,F10)/Inputs!$C$44,Inputs!$C$46),1)) + (Inputs!$C$29*IF(Inputs!$C$43=1,POWER(MAX(1,F10)/Inputs!$C$44,Inputs!$C$46),1)) + (Inputs!$C$30*IF(Inputs!$C$43=1,POWER(MAX(1,F10)/Inputs!$C$44,Inputs!$C$47),1)) + (MAX(Inputs!$C$50, Inputs!$C$33*IF(Inputs!$C$43=1,EXP(-MAX(1,F10)/Inputs!$C$51),1))*Inputs!$C$34) + (Inputs!$C$10*Inputs!$C$35) + Inputs!$C$16*(1/Inputs!$C$18)*Inputs!$C$17 + Inputs!$C$16*Inputs!$C$19*Inputs!$C$17 + Inputs!$C$16*Inputs!$C$20*(Inputs!$C$22 + Inputs!$C$21*Inputs!$C$17) + Inputs!$C$31*(Inputs!$C$7*(1-Inputs!$C$8) - Inputs!$C$7*(1-Inputs!$C$8)*(Inputs!$C$36 + MAX(Inputs!$C$50, Inputs!$C$33*IF(Inputs!$C$43=1,EXP(-MAX(1,F10)/Inputs!$C$51),1))*Inputs!$C$37 + Inputs!$C$10*Inputs!$C$38)) + Inputs!$C$32) | J10: =Inputs!$C$40 + CEILING(F10/Inputs!$C$42,1)*Inputs!$C$41 | K10: =Scale!$B$15
A11: Safety stock factor (variance) | B11: =1 + B10*(B9/IF(B8=0,1,B8)) + Inputs!$C$52 | F11: 3200 | G11: =F11*I11 - J11 | H11: =F11*(I11-K11) - J11 | I11: =((Inputs!$C$7*(1-Inputs!$C$8) - Inputs!$C$7*(1-Inputs!$C$8)*(Inputs!$C$36 + MAX(Inputs!$C$50, Inputs!$C$33*IF(Inputs!$C$43=1,EXP(-MAX(1,F11)/Inputs!$C$51),1))*Inputs!$C$37 + Inputs!$C$10*Inputs!$C$38))) - (Inputs!$C$16*((Inputs!$C$23*IF(Inputs!$C$43=1,POWER(MAX(1,F11)/Inputs!$C$44,Inputs!$C$45),1))+Inputs!$C$24) + (Inputs!$C$25*(1-IF(Inputs!$C$43=1,Inputs!$C$48*(1-EXP(-MAX(1,F11)/Inputs!$C$49)),0))) + (Inputs!$C$26*(1-IF(Inputs!$C$43=1,Inputs!$C$48*(1-EXP(-MAX(1,F11)/Inputs!$C$49)),0))) + Inputs!$C$27 + (Inputs!$C$28*IF(Inputs!$C$43=1,POWER(MAX(1,F11)/Inputs!$C$44,Inputs!$C$46),1)) + (Inputs!$C$29*IF(Inputs!$C$43=1,POWER(MAX(1,F11)/Inputs!$C$44,Inputs!$C$46),1)) + (Inputs!$C$30*IF(Inputs!$C$43=1,POWER(MAX(1,F11)/Inputs!$C$44,Inputs!$C$47),1)) + (MAX(Inputs!$C$50, Inputs!$C$33*IF(Inputs!$C$43=1,EXP(-MAX(1,F11)/Inputs!$C$51),1))*Inputs!$C$34) + (Inputs!$C$10*Inputs!$C$35) + Inputs!$C$16*(1/Inputs!$C$18)*Inputs!$C$17 + Inputs!$C$16*Inputs!$C$19*Inputs!$C$17 + Inputs!$C$16*Inputs!$C$20*(Inputs!$C$22 + Inputs!$C$21*Inputs!$C$17) + Inputs!$C$31*(Inputs!$C$7*(1-Inputs!$C$8) - Inputs!$C$7*(1-Inputs!$C$8)*(Inputs!$C$36 + MAX(Inputs!$C$50, Inputs!$C$33*IF(Inputs!$C$43=1,EXP(-MAX(1,F11)/Inputs!$C$51),1))*Inputs!$C$37 + Inputs!$C$10*Inputs!$C$38)) + Inputs!$C$32) | J11: =Inputs!$C$40 + CEILING(F11/Inputs!$C$42,1)*Inputs!$C$41 | K11: =Scale!$B$15
A12: Inventory multiple (garments per active user) | B12: =Inputs!$C$16*B8*B11 | F12: 4500 | G12: =F12*I12 - J12 | H12: =F12*(I12-K12) - J12 | I12: =((Inputs!$C$7*(1-Inputs!$C$8) - Inputs!$C$7*(1-Inputs!$C$8)*(Inputs!$C$36 + MAX(Inputs!$C$50, Inputs!$C$33*IF(Inputs!$C$43=1,EXP(-MAX(1,F12)/Inputs!$C$51),1))*Inputs!$C$37 + Inputs!$C$10*Inputs!$C$38))) - (Inputs!$C$16*((Inputs!$C$23*IF(Inputs!$C$43=1,POWER(MAX(1,F12)/Inputs!$C$44,Inputs!$C$45),1))+Inputs!$C$24) + (Inputs!$C$25*(1-IF(Inputs!$C$43=1,Inputs!$C$48*(1-EXP(-MAX(1,F12)/Inputs!$C$49)),0))) + (Inputs!$C$26*(1-IF(Inputs!$C$43=1,Inputs!$C$48*(1-EXP(-MAX(1,F12)/Inputs!$C$49)),0))) + Inputs!$C$27 + (Inputs!$C$28*IF(Inputs!$C$43=1,POWER(MAX(1,F12)/Inputs!$C$44,Inputs!$C$46),1)) + (Inputs!$C$29*IF(Inputs!$C$43=1,POWER(MAX(1,F12)/Inputs!$C$44,Inputs!$C$46),1)) + (Inputs!$C$30*IF(Inputs!$C$43=1,POWER(MAX(1,F12)/Inputs!$C$44,Inputs!$C$47),1)) + (MAX(Inputs!$C$50, Inputs!$C$33*IF(Inputs!$C$43=1,EXP(-MAX(1,F12)/Inputs!$C$51),1))*Inputs!$C$34) + (Inputs!$C$10*Inputs!$C$35) + Inputs!$C$16*(1/Inputs!$C$18)*Inputs!$C$17 + Inputs!$C$16*Inputs!$C$19*Inputs!$C$17 + Inputs!$C$16*Inputs!$C$20*(Inputs!$C$22 + Inputs!$C$21*Inputs!$C$17) + Inputs!$C$31*(Inputs!$C$7*(1-Inputs!$C$8) - Inputs!$C$7*(1-Inputs!$C$8)*(Inputs!$C$36 + MAX(Inputs!$C$50, Inputs!$C$33*IF(Inputs!$C$43=1,EXP(-MAX(1,F12)/Inputs!$C$51),1))*Inputs!$C$37 + Inputs!$C$10*Inputs!$C$38)) + Inputs!$C$32) | J12: =Inputs!$C$40 + CEILING(F12/Inputs!$C$42,1)*Inputs!$C$41 | K12: =Scale!$B$15
A13: Required garments (total) | B13: =$B$3*B12 | F13: 6500 | G13: =F13*I13 - J13 | H13: =F13*(I13-K13) - J13 | I13: =((Inputs!$C$7*(1-Inputs!$C$8) - Inputs!$C$7*(1-Inputs!$C$8)*(Inputs!$C$36 + MAX(Inputs!$C$50, Inputs!$C$33*IF(Inputs!$C$43=1,EXP(-MAX(1,F13)/Inputs!$C$51),1))*Inputs!$C$37 + Inputs!$C$10*Inputs!$C$38))) - (Inputs!$C$16*((Inputs!$C$23*IF(Inputs!$C$43=1,POWER(MAX(1,F13)/Inputs!$C$44,Inputs!$C$45),1))+Inputs!$C$24) + (Inputs!$C$25*(1-IF(Inputs!$C$43=1,Inputs!$C$48*(1-EXP(-MAX(1,F13)/Inputs!$C$49)),0))) + (Inputs!$C$26*(1-IF(Inputs!$C$43=1,Inputs!$C$48*(1-EXP(-MAX(1,F13)/Inputs!$C$49)),0))) + Inputs!$C$27 + (Inputs!$C$28*IF(Inputs!$C$43=1,POWER(MAX(1,F13)/Inputs!$C$44,Inputs!$C$46),1)) + (Inputs!$C$29*IF(Inputs!$C$43=1,POWER(MAX(1,F13)/Inputs!$C$44,Inputs!$C$46),1)) + (Inputs!$C$30*IF(Inputs!$C$43=1,POWER(MAX(1,F13)/Inputs!$C$44,Inputs!$C$47),1)) + (MAX(Inputs!$C$50, Inputs!$C$33*IF(Inputs!$C$43=1,EXP(-MAX(1,F13)/Inputs!$C$51),1))*Inputs!$C$34) + (Inputs!$C$10*Inputs!$C$35) + Inputs!$C$16*(1/Inputs!$C$18)*Inputs!$C$17 + Inputs!$C$16*Inputs!$C$19*Inputs!$C$17 + Inputs!$C$16*Inputs!$C$20*(Inputs!$C$22 + Inputs!$C$21*Inputs!$C$17) + Inputs!$C$31*(Inputs!$C$7*(1-Inputs!$C$8) - Inputs!$C$7*(1-Inputs!$C$8)*(Inputs!$C$36 + MAX(Inputs!$C$50, Inputs!$C$33*IF(Inputs!$C$43=1,EXP(-MAX(1,F13)/Inputs!$C$51),1))*Inputs!$C$37 + Inputs!$C$10*Inputs!$C$38)) + Inputs!$C$32) | J13: =Inputs!$C$40 + CEILING(F13/Inputs!$C$42,1)*Inputs!$C$41 | K13: =Scale!$B$15
A14: Inventory capital (USD) | B14: =B13*Inputs!$C$17 | F14: 9000 | G14: =F14*I14 - J14 | H14: =F14*(I14-K14) - J14 | I14: =((Inputs!$C$7*(1-Inputs!$C$8) - Inputs!$C$7*(1-Inputs!$C$8)*(Inputs!$C$36 + MAX(Inputs!$C$50, Inputs!$C$33*IF(Inputs!$C$43=1,EXP(-MAX(1,F14)/Inputs!$C$51),1))*Inputs!$C$37 + Inputs!$C$10*Inputs!$C$38))) - (Inputs!$C$16*((Inputs!$C$23*IF(Inputs!$C$43=1,POWER(MAX(1,F14)/Inputs!$C$44,Inputs!$C$45),1))+Inputs!$C$24) + (Inputs!$C$25*(1-IF(Inputs!$C$43=1,Inputs!$C$48*(1-EXP(-MAX(1,F14)/Inputs!$C$49)),0))) + (Inputs!$C$26*(1-IF(Inputs!$C$43=1,Inputs!$C$48*(1-EXP(-MAX(1,F14)/Inputs!$C$49)),0))) + Inputs!$C$27 + (Inputs!$C$28*IF(Inputs!$C$43=1,POWER(MAX(1,F14)/Inputs!$C$44,Inputs!$C$46),1)) + (Inputs!$C$29*IF(Inputs!$C$43=1,POWER(MAX(1,F14)/Inputs!$C$44,Inputs!$C$46),1)) + (Inputs!$C$30*IF(Inputs!$C$43=1,POWER(MAX(1,F14)/Inputs!$C$44,Inputs!$C$47),1)) + (MAX(Inputs!$C$50, Inputs!$C$33*IF(Inputs!$C$43=1,EXP(-MAX(1,F14)/Inputs!$C$51),1))*Inputs!$C$34) + (Inputs!$C$10*Inputs!$C$35) + Inputs!$C$16*(1/Inputs!$C$18)*Inputs!$C$17 + Inputs!$C$16*Inputs!$C$19*Inputs!$C$17 + Inputs!$C$16*Inputs!$C$20*(Inputs!$C$22 + Inputs!$C$21*Inputs!$C$17) + Inputs!$C$31*(Inputs!$C$7*(1-Inputs!$C$8) - Inputs!$C$7*(1-Inputs!$C$8)*(Inputs!$C$36 + MAX(Inputs!$C$50, Inputs!$C$33*IF(Inputs!$C$43=1,EXP(-MAX(1,F14)/Inputs!$C$51),1))*Inputs!$C$37 + Inputs!$C$10*Inputs!$C$38)) + Inputs!$C$32) | J14: =Inputs!$C$40 + CEILING(F14/Inputs!$C$42,1)*Inputs!$C$41 | K14: =Scale!$B$15
A15: Capital charge per cycle (constant) | B15: =Inputs!$C$39*(B12*Inputs!$C$17) | F15: 12500 | G15: =F15*I15 - J15 | H15: =F15*(I15-K15) - J15 | I15: =((Inputs!$C$7*(1-Inputs!$C$8) - Inputs!$C$7*(1-Inputs!$C$8)*(Inputs!$C$36 + MAX(Inputs!$C$50, Inputs!$C$33*IF(Inputs!$C$43=1,EXP(-MAX(1,F15)/Inputs!$C$51),1))*Inputs!$C$37 + Inputs!$C$10*Inputs!$C$38))) - (Inputs!$C$16*((Inputs!$C$23*IF(Inputs!$C$43=1,POWER(MAX(1,F15)/Inputs!$C$44,Inputs!$C$45),1))+Inputs!$C$24) + (Inputs!$C$25*(1-IF(Inputs!$C$43=1,Inputs!$C$48*(1-EXP(-MAX(1,F15)/Inputs!$C$49)),0))) + (Inputs!$C$26*(1-IF(Inputs!$C$43=1,Inputs!$C$48*(1-EXP(-MAX(1,F15)/Inputs!$C$49)),0))) + Inputs!$C$27 + (Inputs!$C$28*IF(Inputs!$C$43=1,POWER(MAX(1,F15)/Inputs!$C$44,Inputs!$C$46),1)) + (Inputs!$C$29*IF(Inputs!$C$43=1,POWER(MAX(1,F15)/Inputs!$C$44,Inputs!$C$46),1)) + (Inputs!$C$30*IF(Inputs!$C$43=1,POWER(MAX(1,F15)/Inputs!$C$44,Inputs!$C$47),1)) + (MAX(Inputs!$C$50, Inputs!$C$33*IF(Inputs!$C$43=1,EXP(-MAX(1,F15)/Inputs!$C$51),1))*Inputs!$C$34) + (Inputs!$C$10*Inputs!$C$35) + Inputs!$C$16*(1/Inputs!$C$18)*Inputs!$C$17 + Inputs!$C$16*Inputs!$C$19*Inputs!$C$17 + Inputs!$C$16*Inputs!$C$20*(Inputs!$C$22 + Inputs!$C$21*Inputs!$C$17) + Inputs!$C$31*(Inputs!$C$7*(1-Inputs!$C$8) - Inputs!$C$7*(1-Inputs!$C$8)*(Inputs!$C$36 + MAX(Inputs!$C$50, Inputs!$C$33*IF(Inputs!$C$43=1,EXP(-MAX(1,F15)/Inputs!$C$51),1))*Inputs!$C$37 + Inputs!$C$10*Inputs!$C$38)) + Inputs!$C$32) | J15: =Inputs!$C$40 + CEILING(F15/Inputs!$C$42,1)*Inputs!$C$41 | K15: =Scale!$B$15
F16: 17500 | G16: =F16*I16 - J16 | H16: =F16*(I16-K16) - J16 | I16: =((Inputs!$C$7*(1-Inputs!$C$8) - Inputs!$C$7*(1-Inputs!$C$8)*(Inputs!$C$36 + MAX(Inputs!$C$50, Inputs!$C$33*IF(Inputs!$C$43=1,EXP(-MAX(1,F16)/Inputs!$C$51),1))*Inputs!$C$37 + Inputs!$C$10*Inputs!$C$38))) - (Inputs!$C$16*((Inputs!$C$23*IF(Inputs!$C$43=1,POWER(MAX(1,F16)/Inputs!$C$44,Inputs!$C$45),1))+Inputs!$C$24) + (Inputs!$C$25*(1-IF(Inputs!$C$43=1,Inputs!$C$48*(1-EXP(-MAX(1,F16)/Inputs!$C$49)),0))) + (Inputs!$C$26*(1-IF(Inputs!$C$43=1,Inputs!$C$48*(1-EXP(-MAX(1,F16)/Inputs!$C$49)),0))) + Inputs!$C$27 + (Inputs!$C$28*IF(Inputs!$C$43=1,POWER(MAX(1,F16)/Inputs!$C$44,Inputs!$C$46),1)) + (Inputs!$C$29*IF(Inputs!$C$43=1,POWER(MAX(1,F16)/Inputs!$C$44,Inputs!$C$46),1)) + (Inputs!$C$30*IF(Inputs!$C$43=1,POWER(MAX(1,F16)/Inputs!$C$44,Inputs!$C$47),1)) + (MAX(Inputs!$C$50, Inputs!$C$33*IF(Inputs!$C$43=1,EXP(-MAX(1,F16)/Inputs!$C$51),1))*Inputs!$C$34) + (Inputs!$C$10*Inputs!$C$35) + Inputs!$C$16*(1/Inputs!$C$18)*Inputs!$C$17 + Inputs!$C$16*Inputs!$C$19*Inputs!$C$17 + Inputs!$C$16*Inputs!$C$20*(Inputs!$C$22 + Inputs!$C$21*Inputs!$C$17) + Inputs!$C$31*(Inputs!$C$7*(1-Inputs!$C$8) - Inputs!$C$7*(1-Inputs!$C$8)*(Inputs!$C$36 + MAX(Inputs!$C$50, Inputs!$C$33*IF(Inputs!$C$43=1,EXP(-MAX(1,F16)/Inputs!$C$51),1))*Inputs!$C$37 + Inputs!$C$10*Inputs!$C$38)) + Inputs!$C$32) | J16: =Inputs!$C$40 + CEILING(F16/Inputs!$C$42,1)*Inputs!$C$41 | K16: =Scale!$B$15
F17: 24000 | G17: =F17*I17 - J17 | H17: =F17*(I17-K17) - J17 | I17: =((Inputs!$C$7*(1-Inputs!$C$8) - Inputs!$C$7*(1-Inputs!$C$8)*(Inputs!$C$36 + MAX(Inputs!$C$50, Inputs!$C$33*IF(Inputs!$C$43=1,EXP(-MAX(1,F17)/Inputs!$C$51),1))*Inputs!$C$37 + Inputs!$C$10*Inputs!$C$38))) - (Inputs!$C$16*((Inputs!$C$23*IF(Inputs!$C$43=1,POWER(MAX(1,F17)/Inputs!$C$44,Inputs!$C$45),1))+Inputs!$C$24) + (Inputs!$C$25*(1-IF(Inputs!$C$43=1,Inputs!$C$48*(1-EXP(-MAX(1,F17)/Inputs!$C$49)),0))) + (Inputs!$C$26*(1-IF(Inputs!$C$43=1,Inputs!$C$48*(1-EXP(-MAX(1,F17)/Inputs!$C$49)),0))) + Inputs!$C$27 + (Inputs!$C$28*IF(Inputs!$C$43=1,POWER(MAX(1,F17)/Inputs!$C$44,Inputs!$C$46),1)) + (Inputs!$C$29*IF(Inputs!$C$43=1,POWER(MAX(1,F17)/Inputs!$C$44,Inputs!$C$46),1)) + (Inputs!$C$30*IF(Inputs!$C$43=1,POWER(MAX(1,F17)/Inputs!$C$44,Inputs!$C$47),1)) + (MAX(Inputs!$C$50, Inputs!$C$33*IF(Inputs!$C$43=1,EXP(-MAX(1,F17)/Inputs!$C$51),1))*Inputs!$C$34) + (Inputs!$C$10*Inputs!$C$35) + Inputs!$C$16*(1/Inputs!$C$18)*Inputs!$C$17 + Inputs!$C$16*Inputs!$C$19*Inputs!$C$17 + Inputs!$C$16*Inputs!$C$20*(Inputs!$C$22 + Inputs!$C$21*Inputs!$C$17) + Inputs!$C$31*(Inputs!$C$7*(1-Inputs!$C$8) - Inputs!$C$7*(1-Inputs!$C$8)*(Inputs!$C$36 + MAX(Inputs!$C$50, Inputs!$C$33*IF(Inputs!$C$43=1,EXP(-MAX(1,F17)/Inputs!$C$51),1))*Inputs!$C$37 + Inputs!$C$10*Inputs!$C$38)) + Inputs!$C$32) | J17: =Inputs!$C$40 + CEILING(F17/Inputs!$C$42,1)*Inputs!$C$41 | K17: =Scale!$B$15
A18: Weekly P&L (steady-state, per week) | F18: 33000 | G18: =F18*I18 - J18 | H18: =F18*(I18-K18) - J18 | I18: =((Inputs!$C$7*(1-Inputs!$C$8) - Inputs!$C$7*(1-Inputs!$C$8)*(Inputs!$C$36 + MAX(Inputs!$C$50, Inputs!$C$33*IF(Inputs!$C$43=1,EXP(-MAX(1,F18)/Inputs!$C$51),1))*Inputs!$C$37 + Inputs!$C$10*Inputs!$C$38))) - (Inputs!$C$16*((Inputs!$C$23*IF(Inputs!$C$43=1,POWER(MAX(1,F18)/Inputs!$C$44,Inputs!$C$45),1))+Inputs!$C$24) + (Inputs!$C$25*(1-IF(Inputs!$C$43=1,Inputs!$C$48*(1-EXP(-MAX(1,F18)/Inputs!$C$49)),0))) + (Inputs!$C$26*(1-IF(Inputs!$C$43=1,Inputs!$C$48*(1-EXP(-MAX(1,F18)/Inputs!$C$49)),0))) + Inputs!$C$27 + (Inputs!$C$28*IF(Inputs!$C$43=1,POWER(MAX(1,F18)/Inputs!$C$44,Inputs!$C$46),1)) + (Inputs!$C$29*IF(Inputs!$C$43=1,POWER(MAX(1,F18)/Inputs!$C$44,Inputs!$C$46),1)) + (Inputs!$C$30*IF(Inputs!$C$43=1,POWER(MAX(1,F18)/Inputs!$C$44,Inputs!$C$47),1)) + (MAX(Inputs!$C$50, Inputs!$C$33*IF(Inputs!$C$43=1,EXP(-MAX(1,F18)/Inputs!$C$51),1))*Inputs!$C$34) + (Inputs!$C$10*Inputs!$C$35) + Inputs!$C$16*(1/Inputs!$C$18)*Inputs!$C$17 + Inputs!$C$16*Inputs!$C$19*Inputs!$C$17 + Inputs!$C$16*Inputs!$C$20*(Inputs!$C$22 + Inputs!$C$21*Inputs!$C$17) + Inputs!$C$31*(Inputs!$C$7*(1-Inputs!$C$8) - Inputs!$C$7*(1-Inputs!$C$8)*(Inputs!$C$36 + MAX(Inputs!$C$50, Inputs!$C$33*IF(Inputs!$C$43=1,EXP(-MAX(1,F18)/Inputs!$C$51),1))*Inputs!$C$37 + Inputs!$C$10*Inputs!$C$38)) + Inputs!$C$32) | J18: =Inputs!$C$40 + CEILING(F18/Inputs!$C$42,1)*Inputs!$C$41 | K18: =Scale!$B$15
A19: User-week cycles fulfilled | B19: =$B$3 | F19: 45000 | G19: =F19*I19 - J19 | H19: =F19*(I19-K19) - J19 | I19: =((Inputs!$C$7*(1-Inputs!$C$8) - Inputs!$C$7*(1-Inputs!$C$8)*(Inputs!$C$36 + MAX(Inputs!$C$50, Inputs!$C$33*IF(Inputs!$C$43=1,EXP(-MAX(1,F19)/Inputs!$C$51),1))*Inputs!$C$37 + Inputs!$C$10*Inputs!$C$38))) - (Inputs!$C$16*((Inputs!$C$23*IF(Inputs!$C$43=1,POWER(MAX(1,F19)/Inputs!$C$44,Inputs!$C$45),1))+Inputs!$C$24) + (Inputs!$C$25*(1-IF(Inputs!$C$43=1,Inputs!$C$48*(1-EXP(-MAX(1,F19)/Inputs!$C$49)),0))) + (Inputs!$C$26*(1-IF(Inputs!$C$43=1,Inputs!$C$48*(1-EXP(-MAX(1,F19)/Inputs!$C$49)),0))) + Inputs!$C$27 + (Inputs!$C$28*IF(Inputs!$C$43=1,POWER(MAX(1,F19)/Inputs!$C$44,Inputs!$C$46),1)) + (Inputs!$C$29*IF(Inputs!$C$43=1,POWER(MAX(1,F19)/Inputs!$C$44,Inputs!$C$46),1)) + (Inputs!$C$30*IF(Inputs!$C$43=1,POWER(MAX(1,F19)/Inputs!$C$44,Inputs!$C$47),1)) + (MAX(Inputs!$C$50, Inputs!$C$33*IF(Inputs!$C$43=1,EXP(-MAX(1,F19)/Inputs!$C$51),1))*Inputs!$C$34) + (Inputs!$C$10*Inputs!$C$35) + Inputs!$C$16*(1/Inputs!$C$18)*Inputs!$C$17 + Inputs!$C$16*Inputs!$C$19*Inputs!$C$17 + Inputs!$C$16*Inputs!$C$20*(Inputs!$C$22 + Inputs!$C$21*Inputs!$C$17) + Inputs!$C$31*(Inputs!$C$7*(1-Inputs!$C$8) - Inputs!$C$7*(1-Inputs!$C$8)*(Inputs!$C$36 + MAX(Inputs!$C$50, Inputs!$C$33*IF(Inputs!$C$43=1,EXP(-MAX(1,F19)/Inputs!$C$51),1))*Inputs!$C$37 + Inputs!$C$10*Inputs!$C$38)) + Inputs!$C$32) | J19: =Inputs!$C$40 + CEILING(F19/Inputs!$C$42,1)*Inputs!$C$41 | K19: =Scale!$B$15
A20: Net revenue per cycle | B20: =UnitEconomics!$B$18 | F20: 60000 | G20: =F20*I20 - J20 | H20: =F20*(I20-K20) - J20 | I20: =((Inputs!$C$7*(1-Inputs!$C$8) - Inputs!$C$7*(1-Inputs!$C$8)*(Inputs!$C$36 + MAX(Inputs!$C$50, Inputs!$C$33*IF(Inputs!$C$43=1,EXP(-MAX(1,F20)/Inputs!$C$51),1))*Inputs!$C$37 + Inputs!$C$10*Inputs!$C$38))) - (Inputs!$C$16*((Inputs!$C$23*IF(Inputs!$C$43=1,POWER(MAX(1,F20)/Inputs!$C$44,Inputs!$C$45),1))+Inputs!$C$24) + (Inputs!$C$25*(1-IF(Inputs!$C$43=1,Inputs!$C$48*(1-EXP(-MAX(1,F20)/Inputs!$C$49)),0))) + (Inputs!$C$26*(1-IF(Inputs!$C$43=1,Inputs!$C$48*(1-EXP(-MAX(1,F20)/Inputs!$C$49)),0))) + Inputs!$C$27 + (Inputs!$C$28*IF(Inputs!$C$43=1,POWER(MAX(1,F20)/Inputs!$C$44,Inputs!$C$46),1)) + (Inputs!$C$29*IF(Inputs!$C$43=1,POWER(MAX(1,F20)/Inputs!$C$44,Inputs!$C$46),1)) + (Inputs!$C$30*IF(Inputs!$C$43=1,POWER(MAX(1,F20)/Inputs!$C$44,Inputs!$C$47),1)) + (MAX(Inputs!$C$50, Inputs!$C$33*IF(Inputs!$C$43=1,EXP(-MAX(1,F20)/Inputs!$C$51),1))*Inputs!$C$34) + (Inputs!$C$10*Inputs!$C$35) + Inputs!$C$16*(1/Inputs!$C$18)*Inputs!$C$17 + Inputs!$C$16*Inputs!$C$19*Inputs!$C$17 + Inputs!$C$16*Inputs!$C$20*(Inputs!$C$22 + Inputs!$C$21*Inputs!$C$17) + Inputs!$C$31*(Inputs!$C$7*(1-Inputs!$C$8) - Inputs!$C$7*(1-Inputs!$C$8)*(Inputs!$C$36 + MAX(Inputs!$C$50, Inputs!$C$33*IF(Inputs!$C$43=1,EXP(-MAX(1,F20)/Inputs!$C$51),1))*Inputs!$C$37 + Inputs!$C$10*Inputs!$C$38)) + Inputs!$C$32) | J20: =Inputs!$C$40 + CEILING(F20/Inputs!$C$42,1)*Inputs!$C$41 | K20: =Scale!$B$15
A21: Variable cost per cycle | B21: =UnitEconomics!$B$32 | F21: 80000 | G21: =F21*I21 - J21 | H21: =F21*(I21-K21) - J21 | I21: =((Inputs!$C$7*(1-Inputs!$C$8) - Inputs!$C$7*(1-Inputs!$C$8)*(Inputs!$C$36 + MAX(Inputs!$C$50, Inputs!$C$33*IF(Inputs!$C$43=1,EXP(-MAX(1,F21)/Inputs!$C$51),1))*Inputs!$C$37 + Inputs!$C$10*Inputs!$C$38))) - (Inputs!$C$16*((Inputs!$C$23*IF(Inputs!$C$43=1,POWER(MAX(1,F21)/Inputs!$C$44,Inputs!$C$45),1))+Inputs!$C$24) + (Inputs!$C$25*(1-IF(Inputs!$C$43=1,Inputs!$C$48*(1-EXP(-MAX(1,F21)/Inputs!$C$49)),0))) + (Inputs!$C$26*(1-IF(Inputs!$C$43=1,Inputs!$C$48*(1-EXP(-MAX(1,F21)/Inputs!$C$49)),0))) + Inputs!$C$27 + (Inputs!$C$28*IF(Inputs!$C$43=1,POWER(MAX(1,F21)/Inputs!$C$44,Inputs!$C$46),1)) + (Inputs!$C$29*IF(Inputs!$C$43=1,POWER(MAX(1,F21)/Inputs!$C$44,Inputs!$C$46),1)) + (Inputs!$C$30*IF(Inputs!$C$43=1,POWER(MAX(1,F21)/Inputs!$C$44,Inputs!$C$47),1)) + (MAX(Inputs!$C$50, Inputs!$C$33*IF(Inputs!$C$43=1,EXP(-MAX(1,F21)/Inputs!$C$51),1))*Inputs!$C$34) + (Inputs!$C$10*Inputs!$C$35) + Inputs!$C$16*(1/Inputs!$C$18)*Inputs!$C$17 + Inputs!$C$16*Inputs!$C$19*Inputs!$C$17 + Inputs!$C$16*Inputs!$C$20*(Inputs!$C$22 + Inputs!$C$21*Inputs!$C$17) + Inputs!$C$31*(Inputs!$C$7*(1-Inputs!$C$8) - Inputs!$C$7*(1-Inputs!$C$8)*(Inputs!$C$36 + MAX(Inputs!$C$50, Inputs!$C$33*IF(Inputs!$C$43=1,EXP(-MAX(1,F21)/Inputs!$C$51),1))*Inputs!$C$37 + Inputs!$C$10*Inputs!$C$38)) + Inputs!$C$32) | J21: =Inputs!$C$40 + CEILING(F21/Inputs!$C$42,1)*Inputs!$C$41 | K21: =Scale!$B$15
A22: Contribution per cycle | B22: =UnitEconomics!$B$33 | F22: 100000 | G22: =F22*I22 - J22 | H22: =F22*(I22-K22) - J22 | I22: =((Inputs!$C$7*(1-Inputs!$C$8) - Inputs!$C$7*(1-Inputs!$C$8)*(Inputs!$C$36 + MAX(Inputs!$C$50, Inputs!$C$33*IF(Inputs!$C$43=1,EXP(-MAX(1,F22)/Inputs!$C$51),1))*Inputs!$C$37 + Inputs!$C$10*Inputs!$C$38))) - (Inputs!$C$16*((Inputs!$C$23*IF(Inputs!$C$43=1,POWER(MAX(1,F22)/Inputs!$C$44,Inputs!$C$45),1))+Inputs!$C$24) + (Inputs!$C$25*(1-IF(Inputs!$C$43=1,Inputs!$C$48*(1-EXP(-MAX(1,F22)/Inputs!$C$49)),0))) + (Inputs!$C$26*(1-IF(Inputs!$C$43=1,Inputs!$C$48*(1-EXP(-MAX(1,F22)/Inputs!$C$49)),0))) + Inputs!$C$27 + (Inputs!$C$28*IF(Inputs!$C$43=1,POWER(MAX(1,F22)/Inputs!$C$44,Inputs!$C$46),1)) + (Inputs!$C$29*IF(Inputs!$C$43=1,POWER(MAX(1,F22)/Inputs!$C$44,Inputs!$C$46),1)) + (Inputs!$C$30*IF(Inputs!$C$43=1,POWER(MAX(1,F22)/Inputs!$C$44,Inputs!$C$47),1)) + (MAX(Inputs!$C$50, Inputs!$C$33*IF(Inputs!$C$43=1,EXP(-MAX(1,F22)/Inputs!$C$51),1))*Inputs!$C$34) + (Inputs!$C$10*Inputs!$C$35) + Inputs!$C$16*(1/Inputs!$C$18)*Inputs!$C$17 + Inputs!$C$16*Inputs!$C$19*Inputs!$C$17 + Inputs!$C$16*Inputs!$C$20*(Inputs!$C$22 + Inputs!$C$21*Inputs!$C$17) + Inputs!$C$31*(Inputs!$C$7*(1-Inputs!$C$8) - Inputs!$C$7*(1-Inputs!$C$8)*(Inputs!$C$36 + MAX(Inputs!$C$50, Inputs!$C$33*IF(Inputs!$C$43=1,EXP(-MAX(1,F22)/Inputs!$C$51),1))*Inputs!$C$37 + Inputs!$C$10*Inputs!$C$38)) + Inputs!$C$32) | J22: =Inputs!$C$40 + CEILING(F22/Inputs!$C$42,1)*Inputs!$C$41 | K22: =Scale!$B$15
A23: Total contribution (weekly) | B23: =B19*B22
A24: Capital charge per cycle | B24: =B15
A25: Economic contribution per cycle | B25: =B22-B24
A26: Economic contribution (weekly) | B26: =B19*B25
A28: Fixed OPEX & capacity steps
A29: Sites required | B29: =CEILING($B$3/Inputs!$C$42,1)
A30: Fixed OPEX (weekly) | B30: =Inputs!$C$40 + B29*Inputs!$C$41
A31: Operating profit (weekly, CM - fixed) | B31: =B23-B30
A32: Economic profit (weekly, after capital) | B32: =B26-B30
A34: Break-even active users (CM basis) | B34: =IF(B22<=0,"",B30/B22)
A35: Break-even active users (economic CM basis) | B35: =IF(B25<=0,"",B30/B25)
A37: Replacement flow (loss + damage retire + wear retire)
A38: Replacement garments per week | B38: =$B$3*Inputs!$C$16*(Inputs!$C$19 + Inputs!$C$20*Inputs!$C$21 + 1/Inputs!$C$18)
A39: Replacement spend per week | B39: =B38*Inputs!$C$17
A40: Replacement spend per cycle | B40: =IF($B$3=0,0,B39/$B$3)

Sheet Cohorts
A1: Cohort Retention Layer (age-based churn with service-failure shock)
A3: Linked inputs
A4: Horizon (weeks) | B4: =Inputs!$C$62
A5: Start active users | B5: =Inputs!$C$63
A6: Base churn (weekly) | B6: =Inputs!$C$82
A7: Early churn premium | B7: =Inputs!$C$83
A8: Churn decay (weeks) | B8: =Inputs!$C$84
A9: Churn curve by age-week (used for baseline churn weighting; shock applied separately)
A10: Age_wk | B10: Churn_rate | C10: Survival
A11: 0 | B11: =MIN(0.8, Inputs!$C$82*(1+Inputs!$C$83*EXP(-A11/MAX(0.0001,Inputs!$C$84)))) | C11: =1-B11
A12: 1 | B12: =MIN(0.8, Inputs!$C$82*(1+Inputs!$C$83*EXP(-A12/MAX(0.0001,Inputs!$C$84)))) | C12: =1-B12
A13: 2 | B13: =MIN(0.8, Inputs!$C$82*(1+Inputs!$C$83*EXP(-A13/MAX(0.0001,Inputs!$C$84)))) | C13: =1-B13
A14: 3 | B14: =MIN(0.8, Inputs!$C$82*(1+Inputs!$C$83*EXP(-A14/MAX(0.0001,Inputs!$C$84)))) | C14: =1-B14
A15: 4 | B15: =MIN(0.8, Inputs!$C$82*(1+Inputs!$C$83*EXP(-A15/MAX(0.0001,Inputs!$C$84)))) | C15: =1-B15
A16: 5 | B16: =MIN(0.8, Inputs!$C$82*(1+Inputs!$C$83*EXP(-A16/MAX(0.0001,Inputs!$C$84)))) | C16: =1-B16
A17: 6 | B17: =MIN(0.8, Inputs!$C$82*(1+Inputs!$C$83*EXP(-A17/MAX(0.0001,Inputs!$C$84)))) | C17: =1-B17
A18: 7 | B18: =MIN(0.8, Inputs!$C$82*(1+Inputs!$C$83*EXP(-A18/MAX(0.0001,Inputs!$C$84)))) | C18: =1-B18
A19: 8 | B19: =MIN(0.8, Inputs!$C$82*(1+Inputs!$C$83*EXP(-A19/MAX(0.0001,Inputs!$C$84)))) | C19: =1-B19
A20: 9 | B20: =MIN(0.8, Inputs!$C$82*(1+Inputs!$C$83*EXP(-A20/MAX(0.0001,Inputs!$C$84)))) | C20: =1-B20
A21: 10 | B21: =MIN(0.8, Inputs!$C$82*(1+Inputs!$C$83*EXP(-A21/MAX(0.0001,Inputs!$C$84)))) | C21: =1-B21
A22: 11 | B22: =MIN(0.8, Inputs!$C$82*(1+Inputs!$C$83*EXP(-A22/MAX(0.0001,Inputs!$C$84)))) | C22: =1-B22
... A63: 52 | B63: =MIN(0.8, Inputs!$C$82*(1+Inputs!$C$83*EXP(-A63/MAX(0.0001,Inputs!$C$84)))) | C63: =1-B63
A66: Week | B66: Carryover_Users | C66: New_Users | D66: Active_Service | E66: Churn_Shock | F66: Baseline_Churn_Rate | G66: Total_Churn_Rate | H66: Churned | I66: Survivors_End | L66: Age0 | M66: Age1 | N66: Age2 | O66: Age3 | P66: Age4 | Q66: Age5 | R66: Age6 | S66: Age7 | T66: Age8 | U66: Age9 | V66: Age10 | W66: Age11 | X66: Age12 | Y66: Age13 | Z66: Age14 | AA66: Age15 | AB66: Age16 | AC66: Age17 | AD66: Age18 | AE66: Age19 | AF66: Age20 | AG66: Age21 | AH66: Age22 | AI66: Age23 | AJ66: Age24 | AK66: Age25 | AL66: Age26 | AM66: Age27 | AN66: Age28 | AO66: Age29 | AP66: Age30 | AQ66: Age31 | AR66: Age32 | AS66: Age33 | AT66: Age34 | AU66: Age35 | AV66: Age36 | AW66: Age37 | AX66: Age38 | AY66: Age39 | AZ66: Age40 | BA66: Age41 | BB66: Age42 | BC66: Age43 | BD66: Age44 | BE66: Age45 | BF66: Age46 | BG66: Age47 | BH66: Age48 | BI66: Age49 | BJ66: Age50 | BK66: Age51 | BL66: Age52+
A67: 1 | B67: =IF(A67>Inputs!$C$62,"",SUM(M67:BK67)) | C67: =IF(A67>Inputs!$C$62,"",INDEX(Trajectory!$C$23:$C$2000,A67)) | D67: =IF(A67>Inputs!$C$62,"",SUM(L67:BK67)) | E67: =IF(A67>Inputs!$C$62,"",INDEX(Trajectory!$AG$23:$AG$2000,A67)) | F67: =IF(D67=0,0,SUMPRODUCT(L67:BK67,$B$11:$B$63)/D67) | G67: =IF(D67=0,0,MIN(0.95,1-(1-F67)*(1-E67))) | H67: =IF(D67=0,0,D67*G67) | I67: =IF(D67=0,0,D67-H67) | L67: =C67 | M67: 0 | N67: 0 | O67: 0 | P67: 0 | Q67: 0 | R67: 0 | S67: 0 | T67: 0 | U67: 0 | V67: 0 | W67: 0 | X67: 0 | Y67: 0 | Z67: 0 | AA67: 0 | AB67: 0 | AC67: 0 | AD67: 0 | AE67: 0 | AF67: 0 | AG67: 0 | AH67: 0 | AI67: 0 | AJ67: 0 | AK67: 0 | AL67: 0 | AM67: 0 | AN67: 0 | AO67: 0 | AP67: 0 | AQ67: 0 | AR67: 0 | AS67: 0 | AT67: 0 | AU67: 0 | AV67: 0 | AW67: 0 | AX67: 0 | AY67: 0 | AZ67: 0 | BA67: 0 | BB67: 0 | BC67: 0 | BD67: 0 | BE67: 0 | BF67: 0 | BG67: 0 | BH67: 0 | BI67: 0 | BJ67: 0 | BK67: 0 | BL67: =Inputs!$C$63
A68: 2 | B68: =IF(A68>Inputs!$C$62,"",SUM(M68:BK68)) | C68: =IF(A68>Inputs!$C$62,"",INDEX(Trajectory!$C$23:$C$2000,A68)) | D68: =IF(A68>Inputs!$C$62,"",SUM(L68:BK68)) | E68: =IF(A68>Inputs!$C$62,"",INDEX(Trajectory!$AG$23:$AG$2000,A68)) | F68: =IF(D68=0,0,SUMPRODUCT(L68:BK68,$B$11:$B$63)/D68) | G68: =IF(D68=0,0,MIN(0.95,1-(1-F68)*(1-E68))) | H68: =IF(D68=0,0,D68*G68) | I68: =IF(D68=0,0,D68-H68) | L68: =C68 | M68: =MAX(0,L67*(1-INDEX($B$11:$B$63,1))*(1-E67)) | N68: =MAX(0,M67*(1-INDEX($B$11:$B$63,2))*(1-E67)) | O68: =MAX(0,N67*(1-INDEX($B$11:$B$63,3))*(1-E67)) | P68: =MAX(0,O67*(1-INDEX($B$11:$B$63,4))*(1-E67)) | Q68: =MAX(0,P67*(1-INDEX($B$11:$B$63,5))*(1-E67)) | R68: =MAX(0,Q67*(1-INDEX($B$11:$B$63,6))*(1-E67)) | S68: =MAX(0,R67*(1-INDEX($B$11:$B$63,7))*(1-E67)) | T68: =MAX(0,S67*(1-INDEX($B$11:$B$63,8))*(1-E67)) | U68: =MAX(0,T67*(1-INDEX($B$11:$B$63,9))*(1-E67)) | V68: =MAX(0,U67*(1-INDEX($B$11:$B$63,10))*(1-E67)) | W68: =MAX(0,V67*(1-INDEX($B$11:$B$63,11))*(1-E67)) | X68: =MAX(0,W67*(1-INDEX($B$11:$B$63,12))*(1-E67)) | Y68: =MAX(0,X67*(1-INDEX($B$11:$B$63,13))*(1-E67)) | Z68: =MAX(0,Y67*(1-INDEX($B$11:$B$63,14))*(1-E67)) | AA68: =MAX(0,Z67*(1-INDEX($B$11:$B$63,15))*(1-E67)) | AB68: =MAX(0,AA67*(1-INDEX($B$11:$B$63,16))*(1-E67)) | AC68: =MAX(0,AB67*(1-INDEX($B$11:$B$63,17))*(1-E67)) | AD68: =MAX(0,AC67*(1-INDEX($B$11:$B$63,18))*(1-E67)) | AE68: =MAX(0,AD67*(1-INDEX($B$11:$B$63,19))*(1-E67)) | AF68: =MAX(0,AE67*(1-INDEX($B$11:$B$63,20))*(1-E67)) | AG68: =MAX(0,AF67*(1-INDEX($B$11:$B$63,21))*(1-E67)) | AH68: =MAX(0,AG67*(1-INDEX($B$11:$B$63,22))*(1-E67)) | AI68: =MAX(0,AH67*(1-INDEX($B$11:$B$63,23))*(1-E67)) | AJ68: =MAX(0,AI67*(1-INDEX($B$11:$B$63,24))*(1-E67)) | AK68: =MAX(0,AJ67*(1-INDEX($B$11:$B$63,25))*(1-E67)) | AL68: =MAX(0,AK67*(1-INDEX($B$11:$B$63,26))*(1-E67)) | AM68: =MAX(0,AL67*(1-INDEX($B$11:$B$63,27))*(1-E67)) | AN68: =MAX(0,AM67*(1-INDEX($B$11:$B$63,28))*(1-E67)) | AO68: =MAX(0,AN67*(1-INDEX($B$11:$B$63,29))*(1-E67)) | AP68: =MAX(0,AO67*(1-INDEX($B$11:$B$63,30))*(1-E67)) | AQ68: =MAX(0,AP67*(1-INDEX($B$11:$B$63,31))*(1-E67)) | AR68: =MAX(0,AQ67*(1-INDEX($B$11:$B$63,32))*(1-E67)) | AS68: =MAX(0,AR67*(1-INDEX($B$11:$B$63,33))*(1-E67)) | AT68: =MAX(0,AS67*(1-INDEX($B$11:$B$63,34))*(1-E67)) | AU68: =MAX(0,AT67*(1-INDEX($B$11:$B$63,35))*(1-E67)) | AV68: =MAX(0,AU67*(1-INDEX($B$11:$B$63,36))*(1-E67)) | AW68: =MAX(0,AV67*(1-INDEX($B$11:$B$63,37))*(1-E67)) | AX68: =MAX(0,AW67*(1-INDEX($B$11:$B$63,38))*(1-E67)) | AY68: =MAX(0,AX67*(1-INDEX($B$11:$B$63,39))*(1-E67)) | AZ68: =MAX(0,AY67*(1-INDEX($B$11:$B$63,40))*(1-E67)) | BA68: =MAX(0,AZ67*(1-INDEX($B$11:$B$63,41))*(1-E67)) | BB68: =MAX(0,BA67*(1-INDEX($B$11:$B$63,42))*(1-E67)) | BC68: =MAX(0,BB67*(1-INDEX($B$11:$B$63,43))*(1-E67)) | BD68: =MAX(0,BC67*(1-INDEX($B$11:$B$63,44))*(1-E67)) | BE68: =MAX(0,BD67*(1-INDEX($B$11:$B$63,45))*(1-E67)) | BF68: =MAX(0,BE67*(1-INDEX($B$11:$B$63,46))*(1-E67)) | BG68: =MAX(0,BF67*(1-INDEX($B$11:$B$63,47))*(1-E67)) | BH68: =MAX(0,BG67*(1-INDEX($B$11:$B$63,48))*(1-E67)) | BI68: =MAX(0,BH67*(1-INDEX($B$11:$B$63,49))*(1-E67)) | BJ68: =MAX(0,BI67*(1-INDEX($B$11:$B$63,50))*(1-E67)) | BK68: =MAX(0,BJ67*(1-INDEX($B$11:$B$63,51))*(1-E67)) | BL68: =MAX(0,(BL67+BK67)*(1-INDEX($B$11:$B$63,53))*(1-E67))
A69: 3 | B69: =IF(A69>Inputs!$C$62,"",SUM(M69:BK69)) | C69: =IF(A69>Inputs!$C$62,"",INDEX(Trajectory!$C$23:$C$2000,A69)) | D69: =IF(A69>Inputs!$C$62,"",SUM(L69:BK69)) | E69: =IF(A69>Inputs!$C$62,"",INDEX(Trajectory!$AG$23:$AG$2000,A69)) | F69: =IF(D69=0,0,SUMPRODUCT(L69:BK69,$B$11:$B$63)/D69) | G69: =IF(D69=0,0,MIN(0.95,1-(1-F69)*(1-E69))) | H69: =IF(D69=0,0,D69*G69) | I69: =IF(D69=0,0,D69-H69) | L69: =C69 | M69: =MAX(0,L68*(1-INDEX($B$11:$B$63,1))*(1-E68)) | N69: =MAX(0,M68*(1-INDEX($B$11:$B$63,2))*(1-E68)) | O69: =MAX(0,N68*(1-INDEX($B$11:$B$63,3))*(1-E68)) | P69: =MAX(0,O68*(1-INDEX($B$11:$B$63,4))*(1-E68)) | Q69: =MAX(0,P68*(1-INDEX($B$11:$B$63,5))*(1-E68)) | R69: =MAX(0,Q68*(1-INDEX($B$11:$B$63,6))*(1-E68)) | S69: =MAX(0,R68*(1-INDEX($B$11:$B$63,7))*(1-E68)) | T69: =MAX(0,S68*(1-INDEX($B$11:$B$63,8))*(1-E68)) | U69: =MAX(0,T68*(1-INDEX($B$11:$B$63,9))*(1-E68)) | V69: =MAX(0,U68*(1-INDEX($B$11:$B$63,10))*(1-E68)) | W69: =MAX(0,V68*(1-INDEX($B$11:$B$63,11))*(1-E68)) | X69: =MAX(0,W68*(1-INDEX($B$11:$B$63,12))*(1-E68)) | Y69: =MAX(0,X68*(1-INDEX($B$11:$B$63,13))*(1-E68)) | Z69: =MAX(0,Y68*(1-INDEX($B$11:$B$63,14))*(1-E68)) | AA69: =MAX(0,Z68*(1-INDEX($B$11:$B$63,15))*(1-E68)) | AB69: =MAX(0,AA68*(1-INDEX($B$11:$B$63,16))*(1-E68)) | AC69: =MAX(0,AB68*(1-INDEX($B$11:$B$63,17))*(1-E68)) | AD69: =MAX(0,AC68*(1-INDEX($B$11:$B$63,18))*(1-E68)) | AE69: =MAX(0,AD68*(1-INDEX($B$11:$B$63,19))*(1-E68)) | AF69: =MAX(0,AE68*(1-INDEX($B$11:$B$63,20))*(1-E68)) | AG69: =MAX(0,AF68*(1-INDEX($B$11:$B$63,21))*(1-E68)) | AH69: =MAX(0,AG68*(1-INDEX($B$11:$B$63,22))*(1-E68)) | AI69: =MAX(0,AH68*(1-INDEX($B$11:$B$63,23))*(1-E68)) | AJ69: =MAX(0,AI68*(1-INDEX($B$11:$B$63,24))*(1-E68)) | AK69: =MAX(0,AJ68*(1-INDEX($B$11:$B$63,25))*(1-E68)) | AL69: =MAX(0,AK68*(1-INDEX($B$11:$B$63,26))*(1-E68)) | AM69: =MAX(0,AL68*(1-INDEX($B$11:$B$63,27))*(1-E68)) | AN69: =MAX(0,AM68*(1-INDEX($B$11:$B$63,28))*(1-E68)) | AO69: =MAX(0,AN68*(1-INDEX($B$11:$B$63,29))*(1-E68)) | AP69: =MAX(0,AO68*(1-INDEX($B$11:$B$63,30))*(1-E68)) | AQ69: =MAX(0,AP68*(1-INDEX($B$11:$B$63,31))*(1-E68)) | AR69: =MAX(0,AQ68*(1-INDEX($B$11:$B$63,32))*(1-E68)) | AS69: =MAX(0,AR68*(1-INDEX($B$11:$B$63,33))*(1-E68)) | AT69: =MAX(0,AS68*(1-INDEX($B$11:$B$63,34))*(1-E68)) | AU69: =MAX(0,AT68*(1-INDEX($B$11:$B$63,35))*(1-E68)) | AV69: =MAX(0,AU68*(1-INDEX($B$11:$B$63,36))*(1-E68)) | AW69: =MAX(0,AV68*(1-INDEX($B$11:$B$63,37))*(1-E68)) | AX69: =MAX(0,AW68*(1-INDEX($B$11:$B$63,38))*(1-E68)) | AY69: =MAX(0,AX68*(1-INDEX($B$11:$B$63,39))*(1-E68)) | AZ69: =MAX(0,AY68*(1-INDEX($B$11:$B$63,40))*(1-E68)) | BA69: =MAX(0,AZ68*(1-INDEX($B$11:$B$63,41))*(1-E68)) | BB69: =MAX(0,BA68*(1-INDEX($B$11:$B$63,42))*(1-E68)) | BC69: =MAX(0,BB68*(1-INDEX($B$11:$B$63,43))*(1-E68)) | BD69: =MAX(0,BC68*(1-INDEX($B$11:$B$63,44))*(1-E68)) | BE69: =MAX(0,BD68*(1-INDEX($B$11:$B$63,45))*(1-E68)) | BF69: =MAX(0,BE68*(1-INDEX($B$11:$B$63,46))*(1-E68)) | BG69: =MAX(0,BF68*(1-INDEX($B$11:$B$63,47))*(1-E68)) | BH69: =MAX(0,BG68*(1-INDEX($B$11:$B$63,48))*(1-E68)) | BI69: =MAX(0,BH68*(1-INDEX($B$11:$B$63,49))*(1-E68)) | BJ69: =MAX(0,BI68*(1-INDEX($B$11:$B$63,50))*(1-E68)) | BK69: =MAX(0,BJ68*(1-INDEX($B$11:$B$63,51))*(1-E68)) | BL69: =MAX(0,(BL68+BK68)*(1-INDEX($B$11:$B$63,53))*(1-E68))
A70: 4 | B70: =IF(A70>Inputs!$C$62,"",SUM(M70:BK70)) | C70: =IF(A70>Inputs!$C$62,"",INDEX(Trajectory!$C$23:$C$2000,A70)) | D70: =IF(A70>Inputs!$C$62,"",SUM(L70:BK70)) | E70: =IF(A70>Inputs!$C$62,"",INDEX(Trajectory!$AG$23:$AG$2000,A70)) | F70: =IF(D70=0,0,SUMPRODUCT(L70:BK70,$B$11:$B$63)/D70) | G70: =IF(D70=0,0,MIN(0.95,1-(1-F70)*(1-E70))) | H70: =IF(D70=0,0,D70*G70) | I70: =IF(D70=0,0,D70-H70) | L70: =C70 | M70: =MAX(0,L69*(1-INDEX($B$11:$B$63,1))*(1-E69)) | N70: =MAX(0,M69*(1-INDEX($B$11:$B$63,2))*(1-E69)) | O70: =MAX(0,N69*(1-INDEX($B$11:$B$63,3))*(1-E69)) | P70: =MAX(0,O69*(1-INDEX($B$11:$B$63,4))*(1-E69)) | Q70: =MAX(0,P69*(1-INDEX($B$11:$B$63,5))*(1-E69)) | R70: =MAX(0,Q69*(1-INDEX($B$11:$B$63,6))*(1-E69)) | S70: =MAX(0,R69*(1-INDEX($B$11:$B$63,7))*(1-E69)) | T70: =MAX(0,S69*(1-INDEX($B$11:$B$63,8))*(1-E69)) | U70: =MAX(0,T69*(1-INDEX($B$11:$B$63,9))*(1-E69)) | V70: =MAX(0,U69*(1-INDEX($B$11:$B$63,10))*(1-E69)) | W70: =MAX(0,V69*(1-INDEX($B$11:$B$63,11))*(1-E69)) | X70: =MAX(0,W69*(1-INDEX($B$11:$B$63,12))*(1-E69)) | Y70: =MAX(0,X69*(1-INDEX($B$11:$B$63,13))*(1-E69)) | Z70: =MAX(0,Y69*(1-INDEX($B$11:$B$63,14))*(1-E69)) | AA70: =MAX(0,Z69*(1-INDEX($B$11:$B$63,15))*(1-E69)) | AB70: =MAX(0,AA69*(1-INDEX($B$11:$B$63,16))*(1-E69)) | AC70: =MAX(0,AB69*(1-INDEX($B$11:$B$63,17))*(1-E69)) | AD70: =MAX(0,AC69*(1-INDEX($B$11:$B$63,18))*(1-E69)) | AE70: =MAX(0,AD69*(1-INDEX($B$11:$B$63,19))*(1-E69)) | AF70: =MAX(0,AE69*(1-INDEX($B$11:$B$63,20))*(1-E69)) | AG70: =MAX(0,AF69*(1-INDEX($B$11:$B$63,21))*(1-E69)) | AH70: =MAX(0,AG69*(1-INDEX($B$11:$B$63,22))*(1-E69)) | AI70: =MAX(0,AH69*(1-INDEX($B$11:$B$63,23))*(1-E69)) | AJ70: =MAX(0,AI69*(1-INDEX($B$11:$B$63,24))*(1-E69)) | AK70: =MAX(0,AJ69*(1-INDEX($B$11:$B$63,25))*(1-E69)) | AL70: =MAX(0,AK69*(1-INDEX($B$11:$B$63,26))*(1-E69)) | AM70: =MAX(0,AL69*(1-INDEX($B$11:$B$63,27))*(1-E69)) | AN70: =MAX(0,AM69*(1-INDEX($B$11:$B$63,28))*(1-E69)) | AO70: =MAX(0,AN69*(1-INDEX($B$11:$B$63,29))*(1-E69)) | AP70: =MAX(0,AO69*(1-INDEX($B$11:$B$63,30))*(1-E69)) | AQ70: =MAX(0,AP69*(1-INDEX($B$11:$B$63,31))*(1-E69)) | AR70: =MAX(0,AQ69*(1-INDEX($B$11:$B$63,32))*(1-E69)) | AS70: =MAX(0,AR69*(1-INDEX($B$11:$B$63,33))*(1-E69)) | AT70: =MAX(0,AS69*(1-INDEX($B$11:$B$63,34))*(1-E69)) | AU70: =MAX(0,AT69*(1-INDEX($B$11:$B$63,35))*(1-E69)) | AV70: =MAX(0,AU69*(1-INDEX($B$11:$B$63,36))*(1-E69)) | AW70: =MAX(0,AV69*(1-INDEX($B$11:$B$63,37))*(1-E69)) | AX70: =MAX(0,AW69*(1-INDEX($B$11:$B$63,38))*(1-E69)) | AY70: =MAX(0,AX69*(1-INDEX($B$11:$B$63,39))*(1-E69)) | AZ70: =MAX(0,AY69*(1-INDEX($B$11:$B$63,40))*(1-E69)) | BA70: =MAX(0,AZ69*(1-INDEX($B$11:$B$63,41))*(1-E69)) | BB70: =MAX(0,BA69*(1-INDEX($B$11:$B$63,42))*(1-E69)) | BC70: =MAX(0,BB69*(1-INDEX($B$11:$B$63,43))*(1-E69)) | BD70: =MAX(0,BC69*(1-INDEX($B$11:$B$63,44))*(1-E69)) | BE70: =MAX(0,BD69*(1-INDEX($B$11:$B$63,45))*(1-E69)) | BF70: =MAX(0,BE69*(1-INDEX($B$11:$B$63,46))*(1-E69)) | BG70: =MAX(0,BF69*(1-INDEX($B$11:$B$63,47))*(1-E69)) | BH70: =MAX(0,BG69*(1-INDEX($B$11:$B$63,48))*(1-E69)) | BI70: =MAX(0,BH69*(1-INDEX($B$11:$B$63,49))*(1-E69)) | BJ70: =MAX(0,BI69*(1-INDEX($B$11:$B$63,50))*(1-E69)) | BK70: =MAX(0,BJ69*(1-INDEX($B$11:$B$63,51))*(1-E69)) | BL70: =MAX(0,(BL69+BK69)*(1-INDEX($B$11:$B$63,53))*(1-E69))
A71: 5 | B71: =IF(A71>Inputs!$C$62,"",SUM(M71:BK71)) | C71: =IF(A71>Inputs!$C$62,"",INDEX(Trajectory!$C$23:$C$2000,A71)) | D71: =IF(A71>Inputs!$C$62,"",SUM(L71:BK71)) | E71: =IF(A71>Inputs!$C$62,"",INDEX(Trajectory!$AG$23:$AG$2000,A71)) | F71: =IF(D71=0,0,SUMPRODUCT(L71:BK71,$B$11:$B$63)/D71) | G71: =IF(D71=0,0,MIN(0.95,1-(1-F71)*(1-E71))) | H71: =IF(D71=0,0,D71*G71) | I71: =IF(D71=0,0,D71-H71) | L71: =C71 | M71: =MAX(0,L70*(1-INDEX($B$11:$B$63,1))*(1-E70)) | N71: =MAX(0,M70*(1-INDEX($B$11:$B$63,2))*(1-E70)) | O71: =MAX(0,N70*(1-INDEX($B$11:$B$63,3))*(1-E70)) | P71: =MAX(0,O70*(1-INDEX($B$11:$B$63,4))*(1-E70)) | Q71: =MAX(0,P70*(1-INDEX($B$11:$B$63,5))*(1-E70)) | R71: =MAX(0,Q70*(1-INDEX($B$11:$B$63,6))*(1-E70)) | S71: =MAX(0,R70*(1-INDEX($B$11:$B$63,7))*(1-E70)) | T71: =MAX(0,S70*(1-INDEX($B$11:$B$63,8))*(1-E70)) | U71: =MAX(0,T70*(1-INDEX($B$11:$B$63,9))*(1-E70)) | V71: =MAX(0,U70*(1-INDEX($B$11:$B$63,10))*(1-E70)) | W71: =MAX(0,V70*(1-INDEX($B$11:$B$63,11))*(1-E70)) | X71: =MAX(0,W70*(1-INDEX($B$11:$B$63,12))*(1-E70)) | Y71: =MAX(0,X70*(1-INDEX($B$11:$B$63,13))*(1-E70)) | Z71: =MAX(0,Y70*(1-INDEX($B$11:$B$63,14))*(1-E70)) | AA71: =MAX(0,Z70*(1-INDEX($B$11:$B$63,15))*(1-E70)) | AB71: =MAX(0,AA70*(1-INDEX($B$11:$B$63,16))*(1-E70)) | AC71: =MAX(0,AB70*(1-INDEX($B$11:$B$63,17))*(1-E70)) | AD71: =MAX(0,AC70*(1-INDEX($B$11:$B$63,18))*(1-E70)) | AE71: =MAX(0,AD70*(1-INDEX($B$11:$B$63,19))*(1-E70)) | AF71: =MAX(0,AE70*(1-INDEX($B$11:$B$63,20))*(1-E70)) | AG71: =MAX(0,AF70*(1-INDEX($B$11:$B$63,21))*(1-E70)) | AH71: =MAX(0,AG70*(1-INDEX($B$11:$B$63,22))*(1-E70)) | AI71: =MAX(0,AH70*(1-INDEX($B$11:$B$63,23))*(1-E70)) | AJ71: =MAX(0,AI70*(1-INDEX($B$11:$B$63,24))*(1-E70)) | AK71: =MAX(0,AJ70*(1-INDEX($B$11:$B$63,25))*(1-E70)) | AL71: =MAX(0,AK70*(1-INDEX($B$11:$B$63,26))*(1-E70)) | AM71: =MAX(0,AL70*(1-INDEX($B$11:$B$63,27))*(1-E70)) | AN71: =MAX(0,AM70*(1-INDEX($B$11:$B$63,28))*(1-E70)) | AO71: =MAX(0,AN70*(1-INDEX($B$11:$B$63,29))*(1-E70)) | AP71: =MAX(0,AO70*(1-INDEX($B$11:$B$63,30))*(1-E70)) | AQ71: =MAX(0,AP70*(1-INDEX($B$11:$B$63,31))*(1-E70)) | AR71: =MAX(0,AQ70*(1-INDEX($B$11:$B$63,32))*(1-E70)) | AS71: =MAX(0,AR70*(1-INDEX($B$11:$B$63,33))*(1-E70)) | AT71: =MAX(0,AS70*(1-INDEX($B$11:$B$63,34))*(1-E70)) | AU71: =MAX(0,AT70*(1-INDEX($B$11:$B$63,35))*(1-E70)) | AV71: =MAX(0,AU70*(1-INDEX($B$11:$B$63,36))*(1-E70)) | AW71: =MAX(0,AV70*(1-INDEX($B$11:$B$63,37))*(1-E70)) | AX71: =MAX(0,AW70*(1-INDEX($B$11:$B$63,38))*(1-E70)) | AY71: =MAX(0,AX70*(1-INDEX($B$11:$B$63,39))*(1-E70)) | AZ71: =MAX(0,AY70*(1-INDEX($B$11:$B$63,40))*(1-E70)) | BA71: =MAX(0,AZ70*(1-INDEX($B$11:$B$63,41))*(1-E70)) | BB71: =MAX(0,BA70*(1-INDEX($B$11:$B$63,42))*(1-E70)) | BC71: =MAX(0,BB70*(1-INDEX($B$11:$B$63,43))*(1-E70)) | BD71: =MAX(0,BC70*(1-INDEX($B$11:$B$63,44))*(1-E70)) | BE71: =MAX(0,BD70*(1-INDEX($B$11:$B$63,45))*(1-E70)) | BF71: =MAX(0,BE70*(1-INDEX($B$11:$B$63,46))*(1-E70)) | BG71: =MAX(0,BF70*(1-INDEX($B$11:$B$63,47))*(1-E70)) | BH71: =MAX(0,BG70*(1-INDEX($B$11:$B$63,48))*(1-E70)) | BI71: =MAX(0,BH70*(1-INDEX($B$11:$B$63,49))*(1-E70)) | BJ71: =MAX(0,BI70*(1-INDEX($B$11:$B$63,50))*(1-E70)) | BK71: =MAX(0,BJ70*(1-INDEX($B$11:$B$63,51))*(1-E70)) | BL71: =MAX(0,(BL70+BK70)*(1-INDEX($B$11:$B$63,53))*(1-E70))
